WARNING:django.request:Not Found: /accounts/login/
WARNING:django.request:Not Found: /favicon.ico
WARNING:django.request:Not Found: /accounts/login/
WARNING:django.request:Not Found: /ADMIN/
WARNING:django.request:Not Found: /static/admin/css/base.css
WARNING:django.request:Not Found: /static/admin/css/dark_mode.css
WARNING:django.request:Not Found: /static/admin/css/nav_sidebar.css
WARNING:django.request:Not Found: /static/admin/js/theme.js
WARNING:django.request:Not Found: /static/admin/js/nav_sidebar.js
WARNING:django.request:Not Found: /static/admin/css/login.css
WARNING:django.request:Not Found: /static/admin/css/responsive.css
WARNING:django.request:Not Found: /static/admin/css/base.css
WARNING:django.request:Not Found: /static/admin/css/responsive.css
WARNING:django.request:Not Found: /static/admin/css/login.css
WARNING:django.request:Not Found: /static/admin/css/nav_sidebar.css
WARNING:django.request:Not Found: /static/admin/css/dark_mode.css
WARNING:django.request:Not Found: /static/admin/js/theme.js
WARNING:django.request:Not Found: /static/admin/js/nav_sidebar.js
WARNING:django.request:Not Found: /favicon.ico
ERROR:django.request:Internal Server Error: /admin/login/
Traceback (most recent call last):
  File "/usr/local/lib/python3.11/site-packages/django/core/handlers/exception.py", line 55, in inner
    response = get_response(request)
               ^^^^^^^^^^^^^^^^^^^^^
  File "/usr/local/lib/python3.11/site-packages/django/core/handlers/base.py", line 197, in _get_response
    response = wrapped_callback(request, *callback_args, **callback_kwargs)
               ^^^^^^^^^^^^^^^^^^^^^^^^^^^^^^^^^^^^^^^^^^^^^^^^^^^^^^^^^^^^
  File "/usr/local/lib/python3.11/site-packages/django/utils/decorators.py", line 46, in _wrapper
    return bound_method(*args, **kwargs)
           ^^^^^^^^^^^^^^^^^^^^^^^^^^^^^
  File "/usr/local/lib/python3.11/site-packages/django/views/decorators/cache.py", line 62, in _wrapper_view_func
    response = view_func(request, *args, **kwargs)
               ^^^^^^^^^^^^^^^^^^^^^^^^^^^^^^^^^^^
  File "/usr/local/lib/python3.11/site-packages/django/contrib/admin/sites.py", line 441, in login
    return LoginView.as_view(**defaults)(request)
           ^^^^^^^^^^^^^^^^^^^^^^^^^^^^^^^^^^^^^^
  File "/usr/local/lib/python3.11/site-packages/django/views/generic/base.py", line 105, in view
    return self.dispatch(request, *args, **kwargs)
           ^^^^^^^^^^^^^^^^^^^^^^^^^^^^^^^^^^^^^^^
  File "/usr/local/lib/python3.11/site-packages/django/utils/decorators.py", line 46, in _wrapper
    return bound_method(*args, **kwargs)
           ^^^^^^^^^^^^^^^^^^^^^^^^^^^^^
  File "/usr/local/lib/python3.11/site-packages/django/views/decorators/debug.py", line 92, in sensitive_post_parameters_wrapper
    return view(request, *args, **kwargs)
           ^^^^^^^^^^^^^^^^^^^^^^^^^^^^^^
  File "/usr/local/lib/python3.11/site-packages/django/utils/decorators.py", line 46, in _wrapper
    return bound_method(*args, **kwargs)
           ^^^^^^^^^^^^^^^^^^^^^^^^^^^^^
  File "/usr/local/lib/python3.11/site-packages/django/utils/decorators.py", line 134, in _wrapper_view
    response = view_func(request, *args, **kwargs)
               ^^^^^^^^^^^^^^^^^^^^^^^^^^^^^^^^^^^
  File "/usr/local/lib/python3.11/site-packages/django/utils/decorators.py", line 46, in _wrapper
    return bound_method(*args, **kwargs)
           ^^^^^^^^^^^^^^^^^^^^^^^^^^^^^
  File "/usr/local/lib/python3.11/site-packages/django/views/decorators/cache.py", line 62, in _wrapper_view_func
    response = view_func(request, *args, **kwargs)
               ^^^^^^^^^^^^^^^^^^^^^^^^^^^^^^^^^^^
  File "/usr/local/lib/python3.11/site-packages/django/contrib/auth/views.py", line 90, in dispatch
    return super().dispatch(request, *args, **kwargs)
           ^^^^^^^^^^^^^^^^^^^^^^^^^^^^^^^^^^^^^^^^^^
  File "/usr/local/lib/python3.11/site-packages/django/views/generic/base.py", line 144, in dispatch
    return handler(request, *args, **kwargs)
           ^^^^^^^^^^^^^^^^^^^^^^^^^^^^^^^^^
  File "/usr/local/lib/python3.11/site-packages/django/views/generic/edit.py", line 152, in post
    if form.is_valid():
       ^^^^^^^^^^^^^^^
  File "/usr/local/lib/python3.11/site-packages/django/forms/forms.py", line 201, in is_valid
    return self.is_bound and not self.errors
                                 ^^^^^^^^^^^
  File "/usr/local/lib/python3.11/site-packages/django/forms/forms.py", line 196, in errors
    self.full_clean()
  File "/usr/local/lib/python3.11/site-packages/django/forms/forms.py", line 434, in full_clean
    self._clean_form()
  File "/usr/local/lib/python3.11/site-packages/django/forms/forms.py", line 455, in _clean_form
    cleaned_data = self.clean()
                   ^^^^^^^^^^^^
  File "/usr/local/lib/python3.11/site-packages/django/contrib/auth/forms.py", line 252, in clean
    self.user_cache = authenticate(
                      ^^^^^^^^^^^^^
  File "/usr/local/lib/python3.11/site-packages/django/views/decorators/debug.py", line 42, in sensitive_variables_wrapper
    return func(*func_args, **func_kwargs)
           ^^^^^^^^^^^^^^^^^^^^^^^^^^^^^^^
  File "/usr/local/lib/python3.11/site-packages/django/contrib/auth/__init__.py", line 77, in authenticate
    user = backend.authenticate(request, **credentials)
           ^^^^^^^^^^^^^^^^^^^^^^^^^^^^^^^^^^^^^^^^^^^^
  File "/usr/local/lib/python3.11/site-packages/django/contrib/auth/backends.py", line 46, in authenticate
    user = UserModel._default_manager.get_by_natural_key(username)
           ^^^^^^^^^^^^^^^^^^^^^^^^^^^^^^^^^^^^^^^^^^^^^^^^^^^^^^^
  File "/usr/local/lib/python3.11/site-packages/django/contrib/auth/base_user.py", line 54, in get_by_natural_key
    return self.get(**{self.model.USERNAME_FIELD: username})
           ^^^^^^^^^^^^^^^^^^^^^^^^^^^^^^^^^^^^^^^^^^^^^^^^^
  File "/usr/local/lib/python3.11/site-packages/django/db/models/manager.py", line 87, in manager_method
    return getattr(self.get_queryset(), name)(*args, **kwargs)
           ^^^^^^^^^^^^^^^^^^^^^^^^^^^^^^^^^^^^^^^^^^^^^^^^^^^
  File "/usr/local/lib/python3.11/site-packages/django/db/models/query.py", line 633, in get
    num = len(clone)
          ^^^^^^^^^^
  File "/usr/local/lib/python3.11/site-packages/django/db/models/query.py", line 380, in __len__
    self._fetch_all()
  File "/usr/local/lib/python3.11/site-packages/django/db/models/query.py", line 1881, in _fetch_all
    self._result_cache = list(self._iterable_class(self))
                         ^^^^^^^^^^^^^^^^^^^^^^^^^^^^^^^^
  File "/usr/local/lib/python3.11/site-packages/django/db/models/query.py", line 91, in __iter__
    results = compiler.execute_sql(
              ^^^^^^^^^^^^^^^^^^^^^
  File "/usr/local/lib/python3.11/site-packages/django/db/models/sql/compiler.py", line 1560, in execute_sql
    cursor = self.connection.cursor()
             ^^^^^^^^^^^^^^^^^^^^^^^^
  File "/usr/local/lib/python3.11/site-packages/django/utils/asyncio.py", line 26, in inner
    return func(*args, **kwargs)
           ^^^^^^^^^^^^^^^^^^^^^
  File "/usr/local/lib/python3.11/site-packages/django/db/backends/base/base.py", line 329, in cursor
    return self._cursor()
           ^^^^^^^^^^^^^^
  File "/usr/local/lib/python3.11/site-packages/django/db/backends/base/base.py", line 305, in _cursor
    self.ensure_connection()
  File "/usr/local/lib/python3.11/site-packages/django/utils/asyncio.py", line 26, in inner
    return func(*args, **kwargs)
           ^^^^^^^^^^^^^^^^^^^^^
  File "/usr/local/lib/python3.11/site-packages/django/db/backends/base/base.py", line 288, in ensure_connection
    self.connect()
  File "/usr/local/lib/python3.11/site-packages/django/utils/asyncio.py", line 26, in inner
    return func(*args, **kwargs)
           ^^^^^^^^^^^^^^^^^^^^^
  File "/usr/local/lib/python3.11/site-packages/django/db/backends/base/base.py", line 271, in connect
    self.init_connection_state()
  File "/usr/local/lib/python3.11/site-packages/django/db/backends/mysql/base.py", line 257, in init_connection_state
    super().init_connection_state()
  File "/usr/local/lib/python3.11/site-packages/django/db/backends/base/base.py", line 238, in init_connection_state
    self.check_database_version_supported()
  File "/usr/local/lib/python3.11/site-packages/django/db/backends/base/base.py", line 214, in check_database_version_supported
    raise NotSupportedError(
django.db.utils.NotSupportedError: MySQL 8 or later is required (found 5.7.44).
WARNING:django.request:Not Found: /accounts/login/
WARNING:django.request:Not Found: /static/admin/css/base.css
WARNING:django.request:Not Found: /static/admin/css/dark_mode.css
WARNING:django.request:Not Found: /static/admin/css/nav_sidebar.css
WARNING:django.request:Not Found: /static/admin/css/login.css
WARNING:django.request:Not Found: /static/admin/css/responsive.css
WARNING:django.request:Not Found: /static/admin/js/theme.js
WARNING:django.request:Not Found: /static/admin/js/nav_sidebar.js
ERROR:django.request:Internal Server Error: /admin/login/
Traceback (most recent call last):
  File "/usr/local/lib/python3.11/site-packages/django/db/backends/utils.py", line 89, in _execute
    return self.cursor.execute(sql, params)
           ^^^^^^^^^^^^^^^^^^^^^^^^^^^^^^^^
  File "/usr/local/lib/python3.11/site-packages/django/db/backends/mysql/base.py", line 75, in execute
    return self.cursor.execute(query, args)
           ^^^^^^^^^^^^^^^^^^^^^^^^^^^^^^^^
  File "/usr/local/lib/python3.11/site-packages/MySQLdb/cursors.py", line 179, in execute
    res = self._query(mogrified_query)
          ^^^^^^^^^^^^^^^^^^^^^^^^^^^^
  File "/usr/local/lib/python3.11/site-packages/MySQLdb/cursors.py", line 330, in _query
    db.query(q)
  File "/usr/local/lib/python3.11/site-packages/MySQLdb/connections.py", line 280, in query
    _mysql.connection.query(self, query)
MySQLdb.ProgrammingError: (1146, "Table 'poultrysync.orders_customuser' doesn't exist")

The above exception was the direct cause of the following exception:

Traceback (most recent call last):
  File "/usr/local/lib/python3.11/site-packages/django/core/handlers/exception.py", line 55, in inner
    response = get_response(request)
               ^^^^^^^^^^^^^^^^^^^^^
  File "/usr/local/lib/python3.11/site-packages/django/core/handlers/base.py", line 197, in _get_response
    response = wrapped_callback(request, *callback_args, **callback_kwargs)
               ^^^^^^^^^^^^^^^^^^^^^^^^^^^^^^^^^^^^^^^^^^^^^^^^^^^^^^^^^^^^
  File "/usr/local/lib/python3.11/site-packages/django/utils/decorators.py", line 46, in _wrapper
    return bound_method(*args, **kwargs)
           ^^^^^^^^^^^^^^^^^^^^^^^^^^^^^
  File "/usr/local/lib/python3.11/site-packages/django/views/decorators/cache.py", line 62, in _wrapper_view_func
    response = view_func(request, *args, **kwargs)
               ^^^^^^^^^^^^^^^^^^^^^^^^^^^^^^^^^^^
  File "/usr/local/lib/python3.11/site-packages/django/contrib/admin/sites.py", line 441, in login
    return LoginView.as_view(**defaults)(request)
           ^^^^^^^^^^^^^^^^^^^^^^^^^^^^^^^^^^^^^^
  File "/usr/local/lib/python3.11/site-packages/django/views/generic/base.py", line 105, in view
    return self.dispatch(request, *args, **kwargs)
           ^^^^^^^^^^^^^^^^^^^^^^^^^^^^^^^^^^^^^^^
  File "/usr/local/lib/python3.11/site-packages/django/utils/decorators.py", line 46, in _wrapper
    return bound_method(*args, **kwargs)
           ^^^^^^^^^^^^^^^^^^^^^^^^^^^^^
  File "/usr/local/lib/python3.11/site-packages/django/views/decorators/debug.py", line 92, in sensitive_post_parameters_wrapper
    return view(request, *args, **kwargs)
           ^^^^^^^^^^^^^^^^^^^^^^^^^^^^^^
  File "/usr/local/lib/python3.11/site-packages/django/utils/decorators.py", line 46, in _wrapper
    return bound_method(*args, **kwargs)
           ^^^^^^^^^^^^^^^^^^^^^^^^^^^^^
  File "/usr/local/lib/python3.11/site-packages/django/utils/decorators.py", line 134, in _wrapper_view
    response = view_func(request, *args, **kwargs)
               ^^^^^^^^^^^^^^^^^^^^^^^^^^^^^^^^^^^
  File "/usr/local/lib/python3.11/site-packages/django/utils/decorators.py", line 46, in _wrapper
    return bound_method(*args, **kwargs)
           ^^^^^^^^^^^^^^^^^^^^^^^^^^^^^
  File "/usr/local/lib/python3.11/site-packages/django/views/decorators/cache.py", line 62, in _wrapper_view_func
    response = view_func(request, *args, **kwargs)
               ^^^^^^^^^^^^^^^^^^^^^^^^^^^^^^^^^^^
  File "/usr/local/lib/python3.11/site-packages/django/contrib/auth/views.py", line 90, in dispatch
    return super().dispatch(request, *args, **kwargs)
           ^^^^^^^^^^^^^^^^^^^^^^^^^^^^^^^^^^^^^^^^^^
  File "/usr/local/lib/python3.11/site-packages/django/views/generic/base.py", line 144, in dispatch
    return handler(request, *args, **kwargs)
           ^^^^^^^^^^^^^^^^^^^^^^^^^^^^^^^^^
  File "/usr/local/lib/python3.11/site-packages/django/views/generic/edit.py", line 152, in post
    if form.is_valid():
       ^^^^^^^^^^^^^^^
  File "/usr/local/lib/python3.11/site-packages/django/forms/forms.py", line 201, in is_valid
    return self.is_bound and not self.errors
                                 ^^^^^^^^^^^
  File "/usr/local/lib/python3.11/site-packages/django/forms/forms.py", line 196, in errors
    self.full_clean()
  File "/usr/local/lib/python3.11/site-packages/django/forms/forms.py", line 434, in full_clean
    self._clean_form()
  File "/usr/local/lib/python3.11/site-packages/django/forms/forms.py", line 455, in _clean_form
    cleaned_data = self.clean()
                   ^^^^^^^^^^^^
  File "/usr/local/lib/python3.11/site-packages/django/contrib/auth/forms.py", line 252, in clean
    self.user_cache = authenticate(
                      ^^^^^^^^^^^^^
  File "/usr/local/lib/python3.11/site-packages/django/views/decorators/debug.py", line 42, in sensitive_variables_wrapper
    return func(*func_args, **func_kwargs)
           ^^^^^^^^^^^^^^^^^^^^^^^^^^^^^^^
  File "/usr/local/lib/python3.11/site-packages/django/contrib/auth/__init__.py", line 77, in authenticate
    user = backend.authenticate(request, **credentials)
           ^^^^^^^^^^^^^^^^^^^^^^^^^^^^^^^^^^^^^^^^^^^^
  File "/usr/local/lib/python3.11/site-packages/django/contrib/auth/backends.py", line 46, in authenticate
    user = UserModel._default_manager.get_by_natural_key(username)
           ^^^^^^^^^^^^^^^^^^^^^^^^^^^^^^^^^^^^^^^^^^^^^^^^^^^^^^^
  File "/usr/local/lib/python3.11/site-packages/django/contrib/auth/base_user.py", line 54, in get_by_natural_key
    return self.get(**{self.model.USERNAME_FIELD: username})
           ^^^^^^^^^^^^^^^^^^^^^^^^^^^^^^^^^^^^^^^^^^^^^^^^^
  File "/usr/local/lib/python3.11/site-packages/django/db/models/manager.py", line 87, in manager_method
    return getattr(self.get_queryset(), name)(*args, **kwargs)
           ^^^^^^^^^^^^^^^^^^^^^^^^^^^^^^^^^^^^^^^^^^^^^^^^^^^
  File "/usr/local/lib/python3.11/site-packages/django/db/models/query.py", line 633, in get
    num = len(clone)
          ^^^^^^^^^^
  File "/usr/local/lib/python3.11/site-packages/django/db/models/query.py", line 380, in __len__
    self._fetch_all()
  File "/usr/local/lib/python3.11/site-packages/django/db/models/query.py", line 1881, in _fetch_all
    self._result_cache = list(self._iterable_class(self))
                         ^^^^^^^^^^^^^^^^^^^^^^^^^^^^^^^^
  File "/usr/local/lib/python3.11/site-packages/django/db/models/query.py", line 91, in __iter__
    results = compiler.execute_sql(
              ^^^^^^^^^^^^^^^^^^^^^
  File "/usr/local/lib/python3.11/site-packages/django/db/models/sql/compiler.py", line 1562, in execute_sql
    cursor.execute(sql, params)
  File "/usr/local/lib/python3.11/site-packages/django/db/backends/utils.py", line 102, in execute
    return super().execute(sql, params)
           ^^^^^^^^^^^^^^^^^^^^^^^^^^^^
  File "/usr/local/lib/python3.11/site-packages/django/db/backends/utils.py", line 67, in execute
    return self._execute_with_wrappers(
           ^^^^^^^^^^^^^^^^^^^^^^^^^^^^
  File "/usr/local/lib/python3.11/site-packages/django/db/backends/utils.py", line 80, in _execute_with_wrappers
    return executor(sql, params, many, context)
           ^^^^^^^^^^^^^^^^^^^^^^^^^^^^^^^^^^^^
  File "/usr/local/lib/python3.11/site-packages/django/db/backends/utils.py", line 84, in _execute
    with self.db.wrap_database_errors:
  File "/usr/local/lib/python3.11/site-packages/django/db/utils.py", line 91, in __exit__
    raise dj_exc_value.with_traceback(traceback) from exc_value
  File "/usr/local/lib/python3.11/site-packages/django/db/backends/utils.py", line 89, in _execute
    return self.cursor.execute(sql, params)
           ^^^^^^^^^^^^^^^^^^^^^^^^^^^^^^^^
  File "/usr/local/lib/python3.11/site-packages/django/db/backends/mysql/base.py", line 75, in execute
    return self.cursor.execute(query, args)
           ^^^^^^^^^^^^^^^^^^^^^^^^^^^^^^^^
  File "/usr/local/lib/python3.11/site-packages/MySQLdb/cursors.py", line 179, in execute
    res = self._query(mogrified_query)
          ^^^^^^^^^^^^^^^^^^^^^^^^^^^^
  File "/usr/local/lib/python3.11/site-packages/MySQLdb/cursors.py", line 330, in _query
    db.query(q)
  File "/usr/local/lib/python3.11/site-packages/MySQLdb/connections.py", line 280, in query
    _mysql.connection.query(self, query)
django.db.utils.ProgrammingError: (1146, "Table 'poultrysync.orders_customuser' doesn't exist")
WARNING:django.request:Not Found: /accounts/login/
WARNING:django.request:Not Found: /favicon.ico
WARNING:django.request:Not Found: /accounts/login/
WARNING:django.request:Not Found: /favicon.ico
WARNING:django.request:Not Found: /index
WARNING:django.request:Not Found: /index/
INFO:django.utils.autoreload:F:\PycharmProfessional\2024-1-1\c\projects\PoultrySync\u200f\orders\urls.py changed, reloading.
WARNING:django.request:Not Found: /index/
WARNING:django.request:Not Found: /accounts/login/
WARNING:django.request:Not Found: /accounts/login/
INFO:django.utils.autoreload:F:\PycharmProfessional\2024-1-1\c\projects\PoultrySync\u200f\orders\urls.py changed, reloading.
WARNING:django.request:Not Found: /accounts/login/
WARNING:django.request:Not Found: /accounts/login/
INFO:django.utils.autoreload:F:\PycharmProfessional\2024-1-1\c\projects\PoultrySync\u200f\orders\urls.py changed, reloading.
INFO:django.utils.autoreload:F:\PycharmProfessional\2024-1-1\c\projects\PoultrySync\u200f\orders\urls.py changed, reloading.
INFO:django.utils.autoreload:F:\PycharmProfessional\2024-1-1\c\projects\PoultrySync\u200f\poultrysync\settings.py changed, reloading.
WARNING:django.request:Not Found: /accounts/login/
ERROR:django.request:Internal Server Error: /api/token/
Traceback (most recent call last):
  File "F:\PycharmProfessional\2024-1-1\c\projects\PoultrySync\u200f\.venv\Lib\site-packages\django\core\handlers\exception.py", line 55, in inner
    response = get_response(request)
               ^^^^^^^^^^^^^^^^^^^^^
  File "F:\PycharmProfessional\2024-1-1\c\projects\PoultrySync\u200f\.venv\Lib\site-packages\django\core\handlers\base.py", line 220, in _get_response
    response = response.render()
               ^^^^^^^^^^^^^^^^^
  File "F:\PycharmProfessional\2024-1-1\c\projects\PoultrySync\u200f\.venv\Lib\site-packages\django\template\response.py", line 114, in render
    self.content = self.rendered_content
                   ^^^^^^^^^^^^^^^^^^^^^
  File "F:\PycharmProfessional\2024-1-1\c\projects\PoultrySync\u200f\.venv\Lib\site-packages\rest_framework\response.py", line 74, in rendered_content
    ret = renderer.render(self.data, accepted_media_type, context)
          ^^^^^^^^^^^^^^^^^^^^^^^^^^^^^^^^^^^^^^^^^^^^^^^^^^^^^^^^
  File "F:\PycharmProfessional\2024-1-1\c\projects\PoultrySync\u200f\.venv\Lib\site-packages\rest_framework\renderers.py", line 730, in render
    template = loader.get_template(self.template)
               ^^^^^^^^^^^^^^^^^^^^^^^^^^^^^^^^^^
  File "F:\PycharmProfessional\2024-1-1\c\projects\PoultrySync\u200f\.venv\Lib\site-packages\django\template\loader.py", line 19, in get_template
    raise TemplateDoesNotExist(template_name, chain=chain)
django.template.exceptions.TemplateDoesNotExist: rest_framework/api.html
INFO:django.utils.autoreload:F:\PycharmProfessional\2024-1-1\c\projects\PoultrySync\u200f\poultrysync\urls.py changed, reloading.
WARNING:django.request:Not Found: /
ERROR:django.request:Internal Server Error: /swagger/
Traceback (most recent call last):
  File "F:\PycharmProfessional\2024-1-1\c\projects\PoultrySync\u200f\.venv\Lib\site-packages\django\core\handlers\exception.py", line 55, in inner
    response = get_response(request)
               ^^^^^^^^^^^^^^^^^^^^^
  File "F:\PycharmProfessional\2024-1-1\c\projects\PoultrySync\u200f\.venv\Lib\site-packages\django\core\handlers\base.py", line 220, in _get_response
    response = response.render()
               ^^^^^^^^^^^^^^^^^
  File "F:\PycharmProfessional\2024-1-1\c\projects\PoultrySync\u200f\.venv\Lib\site-packages\django\template\response.py", line 114, in render
    self.content = self.rendered_content
                   ^^^^^^^^^^^^^^^^^^^^^
  File "F:\PycharmProfessional\2024-1-1\c\projects\PoultrySync\u200f\.venv\Lib\site-packages\rest_framework\response.py", line 74, in rendered_content
    ret = renderer.render(self.data, accepted_media_type, context)
          ^^^^^^^^^^^^^^^^^^^^^^^^^^^^^^^^^^^^^^^^^^^^^^^^^^^^^^^^
  File "F:\PycharmProfessional\2024-1-1\c\projects\PoultrySync\u200f\.venv\Lib\site-packages\drf_yasg\renderers.py", line 79, in render
    return render_to_string(self.template, renderer_context, renderer_context['request'])
           ^^^^^^^^^^^^^^^^^^^^^^^^^^^^^^^^^^^^^^^^^^^^^^^^^^^^^^^^^^^^^^^^^^^^^^^^^^^^^^
  File "F:\PycharmProfessional\2024-1-1\c\projects\PoultrySync\u200f\.venv\Lib\site-packages\django\template\loader.py", line 61, in render_to_string
    template = get_template(template_name, using=using)
               ^^^^^^^^^^^^^^^^^^^^^^^^^^^^^^^^^^^^^^^^
  File "F:\PycharmProfessional\2024-1-1\c\projects\PoultrySync\u200f\.venv\Lib\site-packages\django\template\loader.py", line 19, in get_template
    raise TemplateDoesNotExist(template_name, chain=chain)
django.template.exceptions.TemplateDoesNotExist: drf-yasg/swagger-ui.html
INFO:django.utils.autoreload:F:\PycharmProfessional\2024-1-1\c\projects\PoultrySync\u200f\poultrysync\settings.py changed, reloading.
WARNING:drf_yasg.inspectors.base:view's ProductViewSet raised exception during schema generation; use `getattr(self, 'swagger_fake_view', False)` to detect and short-circuit this
Traceback (most recent call last):
  File "F:\PycharmProfessional\2024-1-1\c\projects\PoultrySync\u200f\.venv\Lib\site-packages\drf_yasg\inspectors\base.py", line 42, in call_view_method
    return view_method()
           ^^^^^^^^^^^^^
  File "F:\PycharmProfessional\2024-1-1\c\projects\PoultrySync\u200f\orders\views.py", line 23, in get_queryset
    return Product.objects.filter(company=self.request.user.company, is_active=True)
                                          ^^^^^^^^^^^^^^^^^^^^^^^^^
AttributeError: 'AnonymousUser' object has no attribute 'company'
WARNING:drf_yasg.inspectors.base:view's OrderViewSet raised exception during schema generation; use `getattr(self, 'swagger_fake_view', False)` to detect and short-circuit this
Traceback (most recent call last):
  File "F:\PycharmProfessional\2024-1-1\c\projects\PoultrySync\u200f\.venv\Lib\site-packages\drf_yasg\inspectors\base.py", line 42, in call_view_method
    return view_method()
           ^^^^^^^^^^^^^
  File "F:\PycharmProfessional\2024-1-1\c\projects\PoultrySync\u200f\orders\views.py", line 34, in get_queryset
    return Order.objects.filter(company=self.request.user.company)
                                        ^^^^^^^^^^^^^^^^^^^^^^^^^
AttributeError: 'AnonymousUser' object has no attribute 'company'
WARNING:drf_yasg.inspectors.base:view's ProductViewSet raised exception during schema generation; use `getattr(self, 'swagger_fake_view', False)` to detect and short-circuit this
Traceback (most recent call last):
  File "F:\PycharmProfessional\2024-1-1\c\projects\PoultrySync\u200f\.venv\Lib\site-packages\drf_yasg\inspectors\base.py", line 42, in call_view_method
    return view_method()
           ^^^^^^^^^^^^^
  File "F:\PycharmProfessional\2024-1-1\c\projects\PoultrySync\u200f\orders\views.py", line 23, in get_queryset
    return Product.objects.filter(company=self.request.user.company, is_active=True)
                                          ^^^^^^^^^^^^^^^^^^^^^^^^^
AttributeError: 'AnonymousUser' object has no attribute 'company'
WARNING:drf_yasg.inspectors.base:view's OrderViewSet raised exception during schema generation; use `getattr(self, 'swagger_fake_view', False)` to detect and short-circuit this
Traceback (most recent call last):
  File "F:\PycharmProfessional\2024-1-1\c\projects\PoultrySync\u200f\.venv\Lib\site-packages\drf_yasg\inspectors\base.py", line 42, in call_view_method
    return view_method()
           ^^^^^^^^^^^^^
  File "F:\PycharmProfessional\2024-1-1\c\projects\PoultrySync\u200f\orders\views.py", line 34, in get_queryset
    return Order.objects.filter(company=self.request.user.company)
                                        ^^^^^^^^^^^^^^^^^^^^^^^^^
AttributeError: 'AnonymousUser' object has no attribute 'company'
WARNING:drf_yasg.inspectors.base:view's ProductViewSet raised exception during schema generation; use `getattr(self, 'swagger_fake_view', False)` to detect and short-circuit this
Traceback (most recent call last):
  File "F:\PycharmProfessional\2024-1-1\c\projects\PoultrySync\u200f\.venv\Lib\site-packages\drf_yasg\inspectors\base.py", line 42, in call_view_method
    return view_method()
           ^^^^^^^^^^^^^
  File "F:\PycharmProfessional\2024-1-1\c\projects\PoultrySync\u200f\orders\views.py", line 23, in get_queryset
    return Product.objects.filter(company=self.request.user.company, is_active=True)
                                          ^^^^^^^^^^^^^^^^^^^^^^^^^
AttributeError: 'AnonymousUser' object has no attribute 'company'
WARNING:drf_yasg.inspectors.base:view's OrderViewSet raised exception during schema generation; use `getattr(self, 'swagger_fake_view', False)` to detect and short-circuit this
Traceback (most recent call last):
  File "F:\PycharmProfessional\2024-1-1\c\projects\PoultrySync\u200f\.venv\Lib\site-packages\drf_yasg\inspectors\base.py", line 42, in call_view_method
    return view_method()
           ^^^^^^^^^^^^^
  File "F:\PycharmProfessional\2024-1-1\c\projects\PoultrySync\u200f\orders\views.py", line 34, in get_queryset
    return Order.objects.filter(company=self.request.user.company)
                                        ^^^^^^^^^^^^^^^^^^^^^^^^^
AttributeError: 'AnonymousUser' object has no attribute 'company'
WARNING:drf_yasg.inspectors.base:view's ProductViewSet raised exception during schema generation; use `getattr(self, 'swagger_fake_view', False)` to detect and short-circuit this
Traceback (most recent call last):
  File "F:\PycharmProfessional\2024-1-1\c\projects\PoultrySync\u200f\.venv\Lib\site-packages\drf_yasg\inspectors\base.py", line 42, in call_view_method
    return view_method()
           ^^^^^^^^^^^^^
  File "F:\PycharmProfessional\2024-1-1\c\projects\PoultrySync\u200f\orders\views.py", line 23, in get_queryset
    return Product.objects.filter(company=self.request.user.company, is_active=True)
                                          ^^^^^^^^^^^^^^^^^^^^^^^^^
AttributeError: 'AnonymousUser' object has no attribute 'company'
WARNING:drf_yasg.inspectors.base:view's OrderViewSet raised exception during schema generation; use `getattr(self, 'swagger_fake_view', False)` to detect and short-circuit this
Traceback (most recent call last):
  File "F:\PycharmProfessional\2024-1-1\c\projects\PoultrySync\u200f\.venv\Lib\site-packages\drf_yasg\inspectors\base.py", line 42, in call_view_method
    return view_method()
           ^^^^^^^^^^^^^
  File "F:\PycharmProfessional\2024-1-1\c\projects\PoultrySync\u200f\orders\views.py", line 34, in get_queryset
    return Order.objects.filter(company=self.request.user.company)
                                        ^^^^^^^^^^^^^^^^^^^^^^^^^
AttributeError: 'AnonymousUser' object has no attribute 'company'
ERROR:django.request:Internal Server Error: /api/products/
Traceback (most recent call last):
  File "F:\PycharmProfessional\2024-1-1\c\projects\PoultrySync\u200f\.venv\Lib\site-packages\django\core\handlers\exception.py", line 55, in inner
    response = get_response(request)
               ^^^^^^^^^^^^^^^^^^^^^
  File "F:\PycharmProfessional\2024-1-1\c\projects\PoultrySync\u200f\.venv\Lib\site-packages\django\core\handlers\base.py", line 197, in _get_response
    response = wrapped_callback(request, *callback_args, **callback_kwargs)
               ^^^^^^^^^^^^^^^^^^^^^^^^^^^^^^^^^^^^^^^^^^^^^^^^^^^^^^^^^^^^
  File "F:\PycharmProfessional\2024-1-1\c\projects\PoultrySync\u200f\.venv\Lib\site-packages\django\views\decorators\csrf.py", line 56, in wrapper_view
    return view_func(*args, **kwargs)
           ^^^^^^^^^^^^^^^^^^^^^^^^^^
  File "F:\PycharmProfessional\2024-1-1\c\projects\PoultrySync\u200f\.venv\Lib\site-packages\rest_framework\viewsets.py", line 125, in view
    return self.dispatch(request, *args, **kwargs)
           ^^^^^^^^^^^^^^^^^^^^^^^^^^^^^^^^^^^^^^^
  File "F:\PycharmProfessional\2024-1-1\c\projects\PoultrySync\u200f\.venv\Lib\site-packages\rest_framework\views.py", line 515, in dispatch
    response = self.handle_exception(exc)
               ^^^^^^^^^^^^^^^^^^^^^^^^^^
  File "F:\PycharmProfessional\2024-1-1\c\projects\PoultrySync\u200f\.venv\Lib\site-packages\rest_framework\views.py", line 475, in handle_exception
    self.raise_uncaught_exception(exc)
  File "F:\PycharmProfessional\2024-1-1\c\projects\PoultrySync\u200f\.venv\Lib\site-packages\rest_framework\views.py", line 486, in raise_uncaught_exception
    raise exc
  File "F:\PycharmProfessional\2024-1-1\c\projects\PoultrySync\u200f\.venv\Lib\site-packages\rest_framework\views.py", line 503, in dispatch
    self.initial(request, *args, **kwargs)
  File "F:\PycharmProfessional\2024-1-1\c\projects\PoultrySync\u200f\.venv\Lib\site-packages\rest_framework\views.py", line 421, in initial
    self.check_permissions(request)
  File "F:\PycharmProfessional\2024-1-1\c\projects\PoultrySync\u200f\.venv\Lib\site-packages\rest_framework\views.py", line 338, in check_permissions
    if not permission.has_permission(request, self):
           ^^^^^^^^^^^^^^^^^^^^^^^^^^^^^^^^^^^^^^^^
  File "F:\PycharmProfessional\2024-1-1\c\projects\PoultrySync\u200f\orders\permissions.py", line 10, in has_permission
    return request.user.role != 'viewer'
           ^^^^^^^^^^^^^^^^^
AttributeError: 'AnonymousUser' object has no attribute 'role'
INFO:django.utils.autoreload:F:\PycharmProfessional\2024-1-1\c\projects\PoultrySync\u200f\orders\views.py changed, reloading.
WARNING:django.request:Not Found: /accounts/login/
WARNING:django.request:Not Found: /accounts/login/
WARNING:django.request:Unauthorized: /api/products/
INFO:django.utils.autoreload:F:\PycharmProfessional\2024-1-1\c\projects\PoultrySync\u200f\poultrysync\urls.py changed, reloading.
WARNING:drf_yasg.inspectors.base:view's ProductViewSet raised exception during schema generation; use `getattr(self, 'swagger_fake_view', False)` to detect and short-circuit this
Traceback (most recent call last):
  File "F:\PycharmProfessional\2024-1-1\c\projects\PoultrySync\u200f\.venv\Lib\site-packages\drf_yasg\inspectors\base.py", line 42, in call_view_method
    return view_method()
           ^^^^^^^^^^^^^
  File "F:\PycharmProfessional\2024-1-1\c\projects\PoultrySync\u200f\orders\views.py", line 24, in get_queryset
    return Product.objects.filter(company=self.request.user.company, is_active=True)
                                          ^^^^^^^^^^^^^^^^^^^^^^^^^
AttributeError: 'AnonymousUser' object has no attribute 'company'
WARNING:drf_yasg.inspectors.base:view's OrderViewSet raised exception during schema generation; use `getattr(self, 'swagger_fake_view', False)` to detect and short-circuit this
Traceback (most recent call last):
  File "F:\PycharmProfessional\2024-1-1\c\projects\PoultrySync\u200f\.venv\Lib\site-packages\drf_yasg\inspectors\base.py", line 42, in call_view_method
    return view_method()
           ^^^^^^^^^^^^^
  File "F:\PycharmProfessional\2024-1-1\c\projects\PoultrySync\u200f\orders\views.py", line 35, in get_queryset
    return Order.objects.filter(company=self.request.user.company)
                                        ^^^^^^^^^^^^^^^^^^^^^^^^^
AttributeError: 'AnonymousUser' object has no attribute 'company'
WARNING:drf_yasg.inspectors.base:view's ProductViewSet raised exception during schema generation; use `getattr(self, 'swagger_fake_view', False)` to detect and short-circuit this
Traceback (most recent call last):
  File "F:\PycharmProfessional\2024-1-1\c\projects\PoultrySync\u200f\.venv\Lib\site-packages\drf_yasg\inspectors\base.py", line 42, in call_view_method
    return view_method()
           ^^^^^^^^^^^^^
  File "F:\PycharmProfessional\2024-1-1\c\projects\PoultrySync\u200f\orders\views.py", line 24, in get_queryset
    return Product.objects.filter(company=self.request.user.company, is_active=True)
                                          ^^^^^^^^^^^^^^^^^^^^^^^^^
AttributeError: 'AnonymousUser' object has no attribute 'company'
WARNING:drf_yasg.inspectors.base:view's OrderViewSet raised exception during schema generation; use `getattr(self, 'swagger_fake_view', False)` to detect and short-circuit this
Traceback (most recent call last):
  File "F:\PycharmProfessional\2024-1-1\c\projects\PoultrySync\u200f\.venv\Lib\site-packages\drf_yasg\inspectors\base.py", line 42, in call_view_method
    return view_method()
           ^^^^^^^^^^^^^
  File "F:\PycharmProfessional\2024-1-1\c\projects\PoultrySync\u200f\orders\views.py", line 35, in get_queryset
    return Order.objects.filter(company=self.request.user.company)
                                        ^^^^^^^^^^^^^^^^^^^^^^^^^
AttributeError: 'AnonymousUser' object has no attribute 'company'
WARNING:drf_yasg.inspectors.base:view's ProductViewSet raised exception during schema generation; use `getattr(self, 'swagger_fake_view', False)` to detect and short-circuit this
Traceback (most recent call last):
  File "F:\PycharmProfessional\2024-1-1\c\projects\PoultrySync\u200f\.venv\Lib\site-packages\drf_yasg\inspectors\base.py", line 42, in call_view_method
    return view_method()
           ^^^^^^^^^^^^^
  File "F:\PycharmProfessional\2024-1-1\c\projects\PoultrySync\u200f\orders\views.py", line 24, in get_queryset
    return Product.objects.filter(company=self.request.user.company, is_active=True)
                                          ^^^^^^^^^^^^^^^^^^^^^^^^^
AttributeError: 'AnonymousUser' object has no attribute 'company'
WARNING:drf_yasg.inspectors.base:view's OrderViewSet raised exception during schema generation; use `getattr(self, 'swagger_fake_view', False)` to detect and short-circuit this
Traceback (most recent call last):
  File "F:\PycharmProfessional\2024-1-1\c\projects\PoultrySync\u200f\.venv\Lib\site-packages\drf_yasg\inspectors\base.py", line 42, in call_view_method
    return view_method()
           ^^^^^^^^^^^^^
  File "F:\PycharmProfessional\2024-1-1\c\projects\PoultrySync\u200f\orders\views.py", line 35, in get_queryset
    return Order.objects.filter(company=self.request.user.company)
                                        ^^^^^^^^^^^^^^^^^^^^^^^^^
AttributeError: 'AnonymousUser' object has no attribute 'company'
WARNING:drf_yasg.inspectors.base:view's ProductViewSet raised exception during schema generation; use `getattr(self, 'swagger_fake_view', False)` to detect and short-circuit this
Traceback (most recent call last):
  File "F:\PycharmProfessional\2024-1-1\c\projects\PoultrySync\u200f\.venv\Lib\site-packages\drf_yasg\inspectors\base.py", line 42, in call_view_method
    return view_method()
           ^^^^^^^^^^^^^
  File "F:\PycharmProfessional\2024-1-1\c\projects\PoultrySync\u200f\orders\views.py", line 24, in get_queryset
    return Product.objects.filter(company=self.request.user.company, is_active=True)
                                          ^^^^^^^^^^^^^^^^^^^^^^^^^
AttributeError: 'AnonymousUser' object has no attribute 'company'
WARNING:drf_yasg.inspectors.base:view's OrderViewSet raised exception during schema generation; use `getattr(self, 'swagger_fake_view', False)` to detect and short-circuit this
Traceback (most recent call last):
  File "F:\PycharmProfessional\2024-1-1\c\projects\PoultrySync\u200f\.venv\Lib\site-packages\drf_yasg\inspectors\base.py", line 42, in call_view_method
    return view_method()
           ^^^^^^^^^^^^^
  File "F:\PycharmProfessional\2024-1-1\c\projects\PoultrySync\u200f\orders\views.py", line 35, in get_queryset
    return Order.objects.filter(company=self.request.user.company)
                                        ^^^^^^^^^^^^^^^^^^^^^^^^^
AttributeError: 'AnonymousUser' object has no attribute 'company'
WARNING:drf_yasg.inspectors.base:view's ProductViewSet raised exception during schema generation; use `getattr(self, 'swagger_fake_view', False)` to detect and short-circuit this
Traceback (most recent call last):
  File "F:\PycharmProfessional\2024-1-1\c\projects\PoultrySync\u200f\.venv\Lib\site-packages\drf_yasg\inspectors\base.py", line 42, in call_view_method
    return view_method()
           ^^^^^^^^^^^^^
  File "F:\PycharmProfessional\2024-1-1\c\projects\PoultrySync\u200f\orders\views.py", line 24, in get_queryset
    return Product.objects.filter(company=self.request.user.company, is_active=True)
                                          ^^^^^^^^^^^^^^^^^^^^^^^^^
AttributeError: 'AnonymousUser' object has no attribute 'company'
WARNING:drf_yasg.inspectors.base:view's OrderViewSet raised exception during schema generation; use `getattr(self, 'swagger_fake_view', False)` to detect and short-circuit this
Traceback (most recent call last):
  File "F:\PycharmProfessional\2024-1-1\c\projects\PoultrySync\u200f\.venv\Lib\site-packages\drf_yasg\inspectors\base.py", line 42, in call_view_method
    return view_method()
           ^^^^^^^^^^^^^
  File "F:\PycharmProfessional\2024-1-1\c\projects\PoultrySync\u200f\orders\views.py", line 35, in get_queryset
    return Order.objects.filter(company=self.request.user.company)
                                        ^^^^^^^^^^^^^^^^^^^^^^^^^
AttributeError: 'AnonymousUser' object has no attribute 'company'
WARNING:drf_yasg.inspectors.base:view's ProductViewSet raised exception during schema generation; use `getattr(self, 'swagger_fake_view', False)` to detect and short-circuit this
Traceback (most recent call last):
  File "F:\PycharmProfessional\2024-1-1\c\projects\PoultrySync\u200f\.venv\Lib\site-packages\drf_yasg\inspectors\base.py", line 42, in call_view_method
    return view_method()
           ^^^^^^^^^^^^^
  File "F:\PycharmProfessional\2024-1-1\c\projects\PoultrySync\u200f\orders\views.py", line 24, in get_queryset
    return Product.objects.filter(company=self.request.user.company, is_active=True)
                                          ^^^^^^^^^^^^^^^^^^^^^^^^^
AttributeError: 'AnonymousUser' object has no attribute 'company'
WARNING:drf_yasg.inspectors.base:view's OrderViewSet raised exception during schema generation; use `getattr(self, 'swagger_fake_view', False)` to detect and short-circuit this
Traceback (most recent call last):
  File "F:\PycharmProfessional\2024-1-1\c\projects\PoultrySync\u200f\.venv\Lib\site-packages\drf_yasg\inspectors\base.py", line 42, in call_view_method
    return view_method()
           ^^^^^^^^^^^^^
  File "F:\PycharmProfessional\2024-1-1\c\projects\PoultrySync\u200f\orders\views.py", line 35, in get_queryset
    return Order.objects.filter(company=self.request.user.company)
                                        ^^^^^^^^^^^^^^^^^^^^^^^^^
AttributeError: 'AnonymousUser' object has no attribute 'company'
WARNING:drf_yasg.inspectors.base:view's ProductViewSet raised exception during schema generation; use `getattr(self, 'swagger_fake_view', False)` to detect and short-circuit this
Traceback (most recent call last):
  File "F:\PycharmProfessional\2024-1-1\c\projects\PoultrySync\u200f\.venv\Lib\site-packages\drf_yasg\inspectors\base.py", line 42, in call_view_method
    return view_method()
           ^^^^^^^^^^^^^
  File "F:\PycharmProfessional\2024-1-1\c\projects\PoultrySync\u200f\orders\views.py", line 24, in get_queryset
    return Product.objects.filter(company=self.request.user.company, is_active=True)
                                          ^^^^^^^^^^^^^^^^^^^^^^^^^
AttributeError: 'AnonymousUser' object has no attribute 'company'
WARNING:drf_yasg.inspectors.base:view's OrderViewSet raised exception during schema generation; use `getattr(self, 'swagger_fake_view', False)` to detect and short-circuit this
Traceback (most recent call last):
  File "F:\PycharmProfessional\2024-1-1\c\projects\PoultrySync\u200f\.venv\Lib\site-packages\drf_yasg\inspectors\base.py", line 42, in call_view_method
    return view_method()
           ^^^^^^^^^^^^^
  File "F:\PycharmProfessional\2024-1-1\c\projects\PoultrySync\u200f\orders\views.py", line 35, in get_queryset
    return Order.objects.filter(company=self.request.user.company)
                                        ^^^^^^^^^^^^^^^^^^^^^^^^^
AttributeError: 'AnonymousUser' object has no attribute 'company'
WARNING:drf_yasg.inspectors.base:view's ProductViewSet raised exception during schema generation; use `getattr(self, 'swagger_fake_view', False)` to detect and short-circuit this
Traceback (most recent call last):
  File "F:\PycharmProfessional\2024-1-1\c\projects\PoultrySync\u200f\.venv\Lib\site-packages\drf_yasg\inspectors\base.py", line 42, in call_view_method
    return view_method()
           ^^^^^^^^^^^^^
  File "F:\PycharmProfessional\2024-1-1\c\projects\PoultrySync\u200f\orders\views.py", line 24, in get_queryset
    return Product.objects.filter(company=self.request.user.company, is_active=True)
                                          ^^^^^^^^^^^^^^^^^^^^^^^^^
AttributeError: 'AnonymousUser' object has no attribute 'company'
WARNING:drf_yasg.inspectors.base:view's OrderViewSet raised exception during schema generation; use `getattr(self, 'swagger_fake_view', False)` to detect and short-circuit this
Traceback (most recent call last):
  File "F:\PycharmProfessional\2024-1-1\c\projects\PoultrySync\u200f\.venv\Lib\site-packages\drf_yasg\inspectors\base.py", line 42, in call_view_method
    return view_method()
           ^^^^^^^^^^^^^
  File "F:\PycharmProfessional\2024-1-1\c\projects\PoultrySync\u200f\orders\views.py", line 35, in get_queryset
    return Order.objects.filter(company=self.request.user.company)
                                        ^^^^^^^^^^^^^^^^^^^^^^^^^
AttributeError: 'AnonymousUser' object has no attribute 'company'
WARNING:django.request:Not Found: /accounts/login/
INFO:django.utils.autoreload:F:\PycharmProfessional\2024-1-1\c\projects\PoultrySync\u200f\poultrysync\urls.py changed, reloading.
WARNING:drf_yasg.inspectors.base:view's ProductViewSet raised exception during schema generation; use `getattr(self, 'swagger_fake_view', False)` to detect and short-circuit this
Traceback (most recent call last):
  File "F:\PycharmProfessional\2024-1-1\c\projects\PoultrySync\u200f\.venv\Lib\site-packages\drf_yasg\inspectors\base.py", line 42, in call_view_method
    return view_method()
           ^^^^^^^^^^^^^
  File "F:\PycharmProfessional\2024-1-1\c\projects\PoultrySync\u200f\orders\views.py", line 24, in get_queryset
    return Product.objects.filter(company=self.request.user.company, is_active=True)
                                          ^^^^^^^^^^^^^^^^^^^^^^^^^
AttributeError: 'AnonymousUser' object has no attribute 'company'
WARNING:drf_yasg.inspectors.base:view's OrderViewSet raised exception during schema generation; use `getattr(self, 'swagger_fake_view', False)` to detect and short-circuit this
Traceback (most recent call last):
  File "F:\PycharmProfessional\2024-1-1\c\projects\PoultrySync\u200f\.venv\Lib\site-packages\drf_yasg\inspectors\base.py", line 42, in call_view_method
    return view_method()
           ^^^^^^^^^^^^^
  File "F:\PycharmProfessional\2024-1-1\c\projects\PoultrySync\u200f\orders\views.py", line 35, in get_queryset
    return Order.objects.filter(company=self.request.user.company)
                                        ^^^^^^^^^^^^^^^^^^^^^^^^^
AttributeError: 'AnonymousUser' object has no attribute 'company'
WARNING:drf_yasg.inspectors.base:view's ProductViewSet raised exception during schema generation; use `getattr(self, 'swagger_fake_view', False)` to detect and short-circuit this
Traceback (most recent call last):
  File "F:\PycharmProfessional\2024-1-1\c\projects\PoultrySync\u200f\.venv\Lib\site-packages\drf_yasg\inspectors\base.py", line 42, in call_view_method
    return view_method()
           ^^^^^^^^^^^^^
  File "F:\PycharmProfessional\2024-1-1\c\projects\PoultrySync\u200f\orders\views.py", line 24, in get_queryset
    return Product.objects.filter(company=self.request.user.company, is_active=True)
                                          ^^^^^^^^^^^^^^^^^^^^^^^^^
AttributeError: 'AnonymousUser' object has no attribute 'company'
WARNING:drf_yasg.inspectors.base:view's OrderViewSet raised exception during schema generation; use `getattr(self, 'swagger_fake_view', False)` to detect and short-circuit this
Traceback (most recent call last):
  File "F:\PycharmProfessional\2024-1-1\c\projects\PoultrySync\u200f\.venv\Lib\site-packages\drf_yasg\inspectors\base.py", line 42, in call_view_method
    return view_method()
           ^^^^^^^^^^^^^
  File "F:\PycharmProfessional\2024-1-1\c\projects\PoultrySync\u200f\orders\views.py", line 35, in get_queryset
    return Order.objects.filter(company=self.request.user.company)
                                        ^^^^^^^^^^^^^^^^^^^^^^^^^
AttributeError: 'AnonymousUser' object has no attribute 'company'
WARNING:drf_yasg.inspectors.base:view's ProductViewSet raised exception during schema generation; use `getattr(self, 'swagger_fake_view', False)` to detect and short-circuit this
Traceback (most recent call last):
  File "F:\PycharmProfessional\2024-1-1\c\projects\PoultrySync\u200f\.venv\Lib\site-packages\drf_yasg\inspectors\base.py", line 42, in call_view_method
    return view_method()
           ^^^^^^^^^^^^^
  File "F:\PycharmProfessional\2024-1-1\c\projects\PoultrySync\u200f\orders\views.py", line 24, in get_queryset
    return Product.objects.filter(company=self.request.user.company, is_active=True)
                                          ^^^^^^^^^^^^^^^^^^^^^^^^^
AttributeError: 'AnonymousUser' object has no attribute 'company'
WARNING:drf_yasg.inspectors.base:view's OrderViewSet raised exception during schema generation; use `getattr(self, 'swagger_fake_view', False)` to detect and short-circuit this
Traceback (most recent call last):
  File "F:\PycharmProfessional\2024-1-1\c\projects\PoultrySync\u200f\.venv\Lib\site-packages\drf_yasg\inspectors\base.py", line 42, in call_view_method
    return view_method()
           ^^^^^^^^^^^^^
  File "F:\PycharmProfessional\2024-1-1\c\projects\PoultrySync\u200f\orders\views.py", line 35, in get_queryset
    return Order.objects.filter(company=self.request.user.company)
                                        ^^^^^^^^^^^^^^^^^^^^^^^^^
AttributeError: 'AnonymousUser' object has no attribute 'company'
WARNING:drf_yasg.inspectors.base:view's ProductViewSet raised exception during schema generation; use `getattr(self, 'swagger_fake_view', False)` to detect and short-circuit this
Traceback (most recent call last):
  File "F:\PycharmProfessional\2024-1-1\c\projects\PoultrySync\u200f\.venv\Lib\site-packages\drf_yasg\inspectors\base.py", line 42, in call_view_method
    return view_method()
           ^^^^^^^^^^^^^
  File "F:\PycharmProfessional\2024-1-1\c\projects\PoultrySync\u200f\orders\views.py", line 24, in get_queryset
    return Product.objects.filter(company=self.request.user.company, is_active=True)
                                          ^^^^^^^^^^^^^^^^^^^^^^^^^
AttributeError: 'AnonymousUser' object has no attribute 'company'
WARNING:drf_yasg.inspectors.base:view's OrderViewSet raised exception during schema generation; use `getattr(self, 'swagger_fake_view', False)` to detect and short-circuit this
Traceback (most recent call last):
  File "F:\PycharmProfessional\2024-1-1\c\projects\PoultrySync\u200f\.venv\Lib\site-packages\drf_yasg\inspectors\base.py", line 42, in call_view_method
    return view_method()
           ^^^^^^^^^^^^^
  File "F:\PycharmProfessional\2024-1-1\c\projects\PoultrySync\u200f\orders\views.py", line 35, in get_queryset
    return Order.objects.filter(company=self.request.user.company)
                                        ^^^^^^^^^^^^^^^^^^^^^^^^^
AttributeError: 'AnonymousUser' object has no attribute 'company'
WARNING:django.request:Not Found: /accounts/login/
INFO:django.utils.autoreload:F:\PycharmProfessional\2024-1-1\c\projects\PoultrySync\u200f\poultrysync\settings.py changed, reloading.
WARNING:drf_yasg.inspectors.base:view's ProductViewSet raised exception during schema generation; use `getattr(self, 'swagger_fake_view', False)` to detect and short-circuit this
Traceback (most recent call last):
  File "F:\PycharmProfessional\2024-1-1\c\projects\PoultrySync\u200f\.venv\Lib\site-packages\drf_yasg\inspectors\base.py", line 42, in call_view_method
    return view_method()
           ^^^^^^^^^^^^^
  File "F:\PycharmProfessional\2024-1-1\c\projects\PoultrySync\u200f\orders\views.py", line 24, in get_queryset
    return Product.objects.filter(company=self.request.user.company, is_active=True)
                                          ^^^^^^^^^^^^^^^^^^^^^^^^^
AttributeError: 'AnonymousUser' object has no attribute 'company'
WARNING:drf_yasg.inspectors.base:view's OrderViewSet raised exception during schema generation; use `getattr(self, 'swagger_fake_view', False)` to detect and short-circuit this
Traceback (most recent call last):
  File "F:\PycharmProfessional\2024-1-1\c\projects\PoultrySync\u200f\.venv\Lib\site-packages\drf_yasg\inspectors\base.py", line 42, in call_view_method
    return view_method()
           ^^^^^^^^^^^^^
  File "F:\PycharmProfessional\2024-1-1\c\projects\PoultrySync\u200f\orders\views.py", line 35, in get_queryset
    return Order.objects.filter(company=self.request.user.company)
                                        ^^^^^^^^^^^^^^^^^^^^^^^^^
AttributeError: 'AnonymousUser' object has no attribute 'company'
WARNING:drf_yasg.inspectors.base:view's ProductViewSet raised exception during schema generation; use `getattr(self, 'swagger_fake_view', False)` to detect and short-circuit this
Traceback (most recent call last):
  File "F:\PycharmProfessional\2024-1-1\c\projects\PoultrySync\u200f\.venv\Lib\site-packages\drf_yasg\inspectors\base.py", line 42, in call_view_method
    return view_method()
           ^^^^^^^^^^^^^
  File "F:\PycharmProfessional\2024-1-1\c\projects\PoultrySync\u200f\orders\views.py", line 24, in get_queryset
    return Product.objects.filter(company=self.request.user.company, is_active=True)
                                          ^^^^^^^^^^^^^^^^^^^^^^^^^
AttributeError: 'AnonymousUser' object has no attribute 'company'
WARNING:drf_yasg.inspectors.base:view's OrderViewSet raised exception during schema generation; use `getattr(self, 'swagger_fake_view', False)` to detect and short-circuit this
Traceback (most recent call last):
  File "F:\PycharmProfessional\2024-1-1\c\projects\PoultrySync\u200f\.venv\Lib\site-packages\drf_yasg\inspectors\base.py", line 42, in call_view_method
    return view_method()
           ^^^^^^^^^^^^^
  File "F:\PycharmProfessional\2024-1-1\c\projects\PoultrySync\u200f\orders\views.py", line 35, in get_queryset
    return Order.objects.filter(company=self.request.user.company)
                                        ^^^^^^^^^^^^^^^^^^^^^^^^^
AttributeError: 'AnonymousUser' object has no attribute 'company'
WARNING:drf_yasg.inspectors.base:view's ProductViewSet raised exception during schema generation; use `getattr(self, 'swagger_fake_view', False)` to detect and short-circuit this
Traceback (most recent call last):
  File "F:\PycharmProfessional\2024-1-1\c\projects\PoultrySync\u200f\.venv\Lib\site-packages\drf_yasg\inspectors\base.py", line 42, in call_view_method
    return view_method()
           ^^^^^^^^^^^^^
  File "F:\PycharmProfessional\2024-1-1\c\projects\PoultrySync\u200f\orders\views.py", line 24, in get_queryset
    return Product.objects.filter(company=self.request.user.company, is_active=True)
                                          ^^^^^^^^^^^^^^^^^^^^^^^^^
AttributeError: 'AnonymousUser' object has no attribute 'company'
WARNING:drf_yasg.inspectors.base:view's OrderViewSet raised exception during schema generation; use `getattr(self, 'swagger_fake_view', False)` to detect and short-circuit this
Traceback (most recent call last):
  File "F:\PycharmProfessional\2024-1-1\c\projects\PoultrySync\u200f\.venv\Lib\site-packages\drf_yasg\inspectors\base.py", line 42, in call_view_method
    return view_method()
           ^^^^^^^^^^^^^
  File "F:\PycharmProfessional\2024-1-1\c\projects\PoultrySync\u200f\orders\views.py", line 35, in get_queryset
    return Order.objects.filter(company=self.request.user.company)
                                        ^^^^^^^^^^^^^^^^^^^^^^^^^
AttributeError: 'AnonymousUser' object has no attribute 'company'
WARNING:drf_yasg.inspectors.base:view's ProductViewSet raised exception during schema generation; use `getattr(self, 'swagger_fake_view', False)` to detect and short-circuit this
Traceback (most recent call last):
  File "F:\PycharmProfessional\2024-1-1\c\projects\PoultrySync\u200f\.venv\Lib\site-packages\drf_yasg\inspectors\base.py", line 42, in call_view_method
    return view_method()
           ^^^^^^^^^^^^^
  File "F:\PycharmProfessional\2024-1-1\c\projects\PoultrySync\u200f\orders\views.py", line 24, in get_queryset
    return Product.objects.filter(company=self.request.user.company, is_active=True)
                                          ^^^^^^^^^^^^^^^^^^^^^^^^^
AttributeError: 'AnonymousUser' object has no attribute 'company'
WARNING:drf_yasg.inspectors.base:view's OrderViewSet raised exception during schema generation; use `getattr(self, 'swagger_fake_view', False)` to detect and short-circuit this
Traceback (most recent call last):
  File "F:\PycharmProfessional\2024-1-1\c\projects\PoultrySync\u200f\.venv\Lib\site-packages\drf_yasg\inspectors\base.py", line 42, in call_view_method
    return view_method()
           ^^^^^^^^^^^^^
  File "F:\PycharmProfessional\2024-1-1\c\projects\PoultrySync\u200f\orders\views.py", line 35, in get_queryset
    return Order.objects.filter(company=self.request.user.company)
                                        ^^^^^^^^^^^^^^^^^^^^^^^^^
AttributeError: 'AnonymousUser' object has no attribute 'company'
WARNING:django.request:Unauthorized: /api/products/
WARNING:django.request:Unauthorized: /api/products/
WARNING:django.request:Unauthorized: /api/products/
WARNING:django.request:Unauthorized: /api/products/
WARNING:django.request:Unauthorized: /api/products/
INFO:django.utils.autoreload:F:\PycharmProfessional\2024-1-1\c\projects\PoultrySync\u200f\poultrysync\settings.py changed, reloading.
WARNING:django.request:Unauthorized: /api/products/
WARNING:django.request:Unauthorized: /api/products/
WARNING:django.request:Unauthorized: /api/products/
WARNING:django.request:Not Found: /
WARNING:django.request:Not Found: /accounts/login/
WARNING:django.request:Not Found: /accounts/login/
INFO:django.utils.autoreload:F:\PycharmProfessional\2024-1-1\c\projects\PoultrySync\u200f\poultrysync\settings.py changed, reloading.
INFO:django.utils.autoreload:F:\PycharmProfessional\2024-1-1\c\projects\PoultrySync\u200f\poultrysync\urls.py changed, reloading.
INFO:django.utils.autoreload:F:\PycharmProfessional\2024-1-1\c\projects\PoultrySync\u200f\poultrysync\urls.py changed, reloading.
WARNING:django.request:Not Found: /
WARNING:drf_yasg.inspectors.base:view's ProductViewSet raised exception during schema generation; use `getattr(self, 'swagger_fake_view', False)` to detect and short-circuit this
Traceback (most recent call last):
  File "F:\PycharmProfessional\2024-1-1\c\projects\PoultrySync\u200f\.venv\Lib\site-packages\drf_yasg\inspectors\base.py", line 42, in call_view_method
    return view_method()
           ^^^^^^^^^^^^^
  File "F:\PycharmProfessional\2024-1-1\c\projects\PoultrySync\u200f\orders\views.py", line 24, in get_queryset
    return Product.objects.filter(company=self.request.user.company, is_active=True)
                                          ^^^^^^^^^^^^^^^^^^^^^^^^^
AttributeError: 'AnonymousUser' object has no attribute 'company'
WARNING:drf_yasg.inspectors.base:view's OrderViewSet raised exception during schema generation; use `getattr(self, 'swagger_fake_view', False)` to detect and short-circuit this
Traceback (most recent call last):
  File "F:\PycharmProfessional\2024-1-1\c\projects\PoultrySync\u200f\.venv\Lib\site-packages\drf_yasg\inspectors\base.py", line 42, in call_view_method
    return view_method()
           ^^^^^^^^^^^^^
  File "F:\PycharmProfessional\2024-1-1\c\projects\PoultrySync\u200f\orders\views.py", line 35, in get_queryset
    return Order.objects.filter(company=self.request.user.company)
                                        ^^^^^^^^^^^^^^^^^^^^^^^^^
AttributeError: 'AnonymousUser' object has no attribute 'company'
WARNING:drf_yasg.inspectors.base:view's ProductViewSet raised exception during schema generation; use `getattr(self, 'swagger_fake_view', False)` to detect and short-circuit this
Traceback (most recent call last):
  File "F:\PycharmProfessional\2024-1-1\c\projects\PoultrySync\u200f\.venv\Lib\site-packages\drf_yasg\inspectors\base.py", line 42, in call_view_method
    return view_method()
           ^^^^^^^^^^^^^
  File "F:\PycharmProfessional\2024-1-1\c\projects\PoultrySync\u200f\orders\views.py", line 24, in get_queryset
    return Product.objects.filter(company=self.request.user.company, is_active=True)
                                          ^^^^^^^^^^^^^^^^^^^^^^^^^
AttributeError: 'AnonymousUser' object has no attribute 'company'
WARNING:drf_yasg.inspectors.base:view's OrderViewSet raised exception during schema generation; use `getattr(self, 'swagger_fake_view', False)` to detect and short-circuit this
Traceback (most recent call last):
  File "F:\PycharmProfessional\2024-1-1\c\projects\PoultrySync\u200f\.venv\Lib\site-packages\drf_yasg\inspectors\base.py", line 42, in call_view_method
    return view_method()
           ^^^^^^^^^^^^^
  File "F:\PycharmProfessional\2024-1-1\c\projects\PoultrySync\u200f\orders\views.py", line 35, in get_queryset
    return Order.objects.filter(company=self.request.user.company)
                                        ^^^^^^^^^^^^^^^^^^^^^^^^^
AttributeError: 'AnonymousUser' object has no attribute 'company'
WARNING:drf_yasg.inspectors.base:view's ProductViewSet raised exception during schema generation; use `getattr(self, 'swagger_fake_view', False)` to detect and short-circuit this
Traceback (most recent call last):
  File "F:\PycharmProfessional\2024-1-1\c\projects\PoultrySync\u200f\.venv\Lib\site-packages\drf_yasg\inspectors\base.py", line 42, in call_view_method
    return view_method()
           ^^^^^^^^^^^^^
  File "F:\PycharmProfessional\2024-1-1\c\projects\PoultrySync\u200f\orders\views.py", line 24, in get_queryset
    return Product.objects.filter(company=self.request.user.company, is_active=True)
                                          ^^^^^^^^^^^^^^^^^^^^^^^^^
AttributeError: 'AnonymousUser' object has no attribute 'company'
WARNING:drf_yasg.inspectors.base:view's OrderViewSet raised exception during schema generation; use `getattr(self, 'swagger_fake_view', False)` to detect and short-circuit this
Traceback (most recent call last):
  File "F:\PycharmProfessional\2024-1-1\c\projects\PoultrySync\u200f\.venv\Lib\site-packages\drf_yasg\inspectors\base.py", line 42, in call_view_method
    return view_method()
           ^^^^^^^^^^^^^
  File "F:\PycharmProfessional\2024-1-1\c\projects\PoultrySync\u200f\orders\views.py", line 35, in get_queryset
    return Order.objects.filter(company=self.request.user.company)
                                        ^^^^^^^^^^^^^^^^^^^^^^^^^
AttributeError: 'AnonymousUser' object has no attribute 'company'
WARNING:drf_yasg.inspectors.base:view's ProductViewSet raised exception during schema generation; use `getattr(self, 'swagger_fake_view', False)` to detect and short-circuit this
Traceback (most recent call last):
  File "F:\PycharmProfessional\2024-1-1\c\projects\PoultrySync\u200f\.venv\Lib\site-packages\drf_yasg\inspectors\base.py", line 42, in call_view_method
    return view_method()
           ^^^^^^^^^^^^^
  File "F:\PycharmProfessional\2024-1-1\c\projects\PoultrySync\u200f\orders\views.py", line 24, in get_queryset
    return Product.objects.filter(company=self.request.user.company, is_active=True)
                                          ^^^^^^^^^^^^^^^^^^^^^^^^^
AttributeError: 'AnonymousUser' object has no attribute 'company'
WARNING:drf_yasg.inspectors.base:view's OrderViewSet raised exception during schema generation; use `getattr(self, 'swagger_fake_view', False)` to detect and short-circuit this
Traceback (most recent call last):
  File "F:\PycharmProfessional\2024-1-1\c\projects\PoultrySync\u200f\.venv\Lib\site-packages\drf_yasg\inspectors\base.py", line 42, in call_view_method
    return view_method()
           ^^^^^^^^^^^^^
  File "F:\PycharmProfessional\2024-1-1\c\projects\PoultrySync\u200f\orders\views.py", line 35, in get_queryset
    return Order.objects.filter(company=self.request.user.company)
                                        ^^^^^^^^^^^^^^^^^^^^^^^^^
AttributeError: 'AnonymousUser' object has no attribute 'company'
WARNING:django.request:Bad Request: /api/orders/
WARNING:django.request:Bad Request: /api/orders/
WARNING:django.request:Forbidden: /api/orders/
INFO:django.utils.autoreload:F:\PycharmProfessional\2024-1-1\c\projects\PoultrySync\u200f\orders\serializers.py changed, reloading.
WARNING:drf_yasg.inspectors.base:view's ProductViewSet raised exception during schema generation; use `getattr(self, 'swagger_fake_view', False)` to detect and short-circuit this
Traceback (most recent call last):
  File "F:\PycharmProfessional\2024-1-1\c\projects\PoultrySync\u200f\.venv\Lib\site-packages\drf_yasg\inspectors\base.py", line 42, in call_view_method
    return view_method()
           ^^^^^^^^^^^^^
  File "F:\PycharmProfessional\2024-1-1\c\projects\PoultrySync\u200f\orders\views.py", line 24, in get_queryset
    return Product.objects.filter(company=self.request.user.company, is_active=True)
                                          ^^^^^^^^^^^^^^^^^^^^^^^^^
AttributeError: 'AnonymousUser' object has no attribute 'company'
WARNING:drf_yasg.inspectors.base:view's OrderViewSet raised exception during schema generation; use `getattr(self, 'swagger_fake_view', False)` to detect and short-circuit this
Traceback (most recent call last):
  File "F:\PycharmProfessional\2024-1-1\c\projects\PoultrySync\u200f\.venv\Lib\site-packages\drf_yasg\inspectors\base.py", line 42, in call_view_method
    return view_method()
           ^^^^^^^^^^^^^
  File "F:\PycharmProfessional\2024-1-1\c\projects\PoultrySync\u200f\orders\views.py", line 35, in get_queryset
    return Order.objects.filter(company=self.request.user.company)
                                        ^^^^^^^^^^^^^^^^^^^^^^^^^
AttributeError: 'AnonymousUser' object has no attribute 'company'
WARNING:drf_yasg.inspectors.base:view's ProductViewSet raised exception during schema generation; use `getattr(self, 'swagger_fake_view', False)` to detect and short-circuit this
Traceback (most recent call last):
  File "F:\PycharmProfessional\2024-1-1\c\projects\PoultrySync\u200f\.venv\Lib\site-packages\drf_yasg\inspectors\base.py", line 42, in call_view_method
    return view_method()
           ^^^^^^^^^^^^^
  File "F:\PycharmProfessional\2024-1-1\c\projects\PoultrySync\u200f\orders\views.py", line 24, in get_queryset
    return Product.objects.filter(company=self.request.user.company, is_active=True)
                                          ^^^^^^^^^^^^^^^^^^^^^^^^^
AttributeError: 'AnonymousUser' object has no attribute 'company'
WARNING:drf_yasg.inspectors.base:view's OrderViewSet raised exception during schema generation; use `getattr(self, 'swagger_fake_view', False)` to detect and short-circuit this
Traceback (most recent call last):
  File "F:\PycharmProfessional\2024-1-1\c\projects\PoultrySync\u200f\.venv\Lib\site-packages\drf_yasg\inspectors\base.py", line 42, in call_view_method
    return view_method()
           ^^^^^^^^^^^^^
  File "F:\PycharmProfessional\2024-1-1\c\projects\PoultrySync\u200f\orders\views.py", line 35, in get_queryset
    return Order.objects.filter(company=self.request.user.company)
                                        ^^^^^^^^^^^^^^^^^^^^^^^^^
AttributeError: 'AnonymousUser' object has no attribute 'company'
WARNING:drf_yasg.inspectors.base:view's ProductViewSet raised exception during schema generation; use `getattr(self, 'swagger_fake_view', False)` to detect and short-circuit this
Traceback (most recent call last):
  File "F:\PycharmProfessional\2024-1-1\c\projects\PoultrySync\u200f\.venv\Lib\site-packages\drf_yasg\inspectors\base.py", line 42, in call_view_method
    return view_method()
           ^^^^^^^^^^^^^
  File "F:\PycharmProfessional\2024-1-1\c\projects\PoultrySync\u200f\orders\views.py", line 24, in get_queryset
    return Product.objects.filter(company=self.request.user.company, is_active=True)
                                          ^^^^^^^^^^^^^^^^^^^^^^^^^
AttributeError: 'AnonymousUser' object has no attribute 'company'
WARNING:drf_yasg.inspectors.base:view's OrderViewSet raised exception during schema generation; use `getattr(self, 'swagger_fake_view', False)` to detect and short-circuit this
Traceback (most recent call last):
  File "F:\PycharmProfessional\2024-1-1\c\projects\PoultrySync\u200f\.venv\Lib\site-packages\drf_yasg\inspectors\base.py", line 42, in call_view_method
    return view_method()
           ^^^^^^^^^^^^^
  File "F:\PycharmProfessional\2024-1-1\c\projects\PoultrySync\u200f\orders\views.py", line 35, in get_queryset
    return Order.objects.filter(company=self.request.user.company)
                                        ^^^^^^^^^^^^^^^^^^^^^^^^^
AttributeError: 'AnonymousUser' object has no attribute 'company'
WARNING:drf_yasg.inspectors.base:view's ProductViewSet raised exception during schema generation; use `getattr(self, 'swagger_fake_view', False)` to detect and short-circuit this
Traceback (most recent call last):
  File "F:\PycharmProfessional\2024-1-1\c\projects\PoultrySync\u200f\.venv\Lib\site-packages\drf_yasg\inspectors\base.py", line 42, in call_view_method
    return view_method()
           ^^^^^^^^^^^^^
  File "F:\PycharmProfessional\2024-1-1\c\projects\PoultrySync\u200f\orders\views.py", line 24, in get_queryset
    return Product.objects.filter(company=self.request.user.company, is_active=True)
                                          ^^^^^^^^^^^^^^^^^^^^^^^^^
AttributeError: 'AnonymousUser' object has no attribute 'company'
WARNING:drf_yasg.inspectors.base:view's OrderViewSet raised exception during schema generation; use `getattr(self, 'swagger_fake_view', False)` to detect and short-circuit this
Traceback (most recent call last):
  File "F:\PycharmProfessional\2024-1-1\c\projects\PoultrySync\u200f\.venv\Lib\site-packages\drf_yasg\inspectors\base.py", line 42, in call_view_method
    return view_method()
           ^^^^^^^^^^^^^
  File "F:\PycharmProfessional\2024-1-1\c\projects\PoultrySync\u200f\orders\views.py", line 35, in get_queryset
    return Order.objects.filter(company=self.request.user.company)
                                        ^^^^^^^^^^^^^^^^^^^^^^^^^
AttributeError: 'AnonymousUser' object has no attribute 'company'
WARNING:django.request:Forbidden: /api/orders/4/
ERROR:django.request:Internal Server Error: /api/orders/4/
Traceback (most recent call last):
  File "F:\PycharmProfessional\2024-1-1\c\projects\PoultrySync\u200f\.venv\Lib\site-packages\django\core\handlers\exception.py", line 55, in inner
    response = get_response(request)
               ^^^^^^^^^^^^^^^^^^^^^
  File "F:\PycharmProfessional\2024-1-1\c\projects\PoultrySync\u200f\.venv\Lib\site-packages\django\core\handlers\base.py", line 197, in _get_response
    response = wrapped_callback(request, *callback_args, **callback_kwargs)
               ^^^^^^^^^^^^^^^^^^^^^^^^^^^^^^^^^^^^^^^^^^^^^^^^^^^^^^^^^^^^
  File "F:\PycharmProfessional\2024-1-1\c\projects\PoultrySync\u200f\.venv\Lib\site-packages\django\views\decorators\csrf.py", line 56, in wrapper_view
    return view_func(*args, **kwargs)
           ^^^^^^^^^^^^^^^^^^^^^^^^^^
  File "F:\PycharmProfessional\2024-1-1\c\projects\PoultrySync\u200f\.venv\Lib\site-packages\rest_framework\viewsets.py", line 125, in view
    return self.dispatch(request, *args, **kwargs)
           ^^^^^^^^^^^^^^^^^^^^^^^^^^^^^^^^^^^^^^^
  File "F:\PycharmProfessional\2024-1-1\c\projects\PoultrySync\u200f\.venv\Lib\site-packages\rest_framework\views.py", line 515, in dispatch
    response = self.handle_exception(exc)
               ^^^^^^^^^^^^^^^^^^^^^^^^^^
  File "F:\PycharmProfessional\2024-1-1\c\projects\PoultrySync\u200f\.venv\Lib\site-packages\rest_framework\views.py", line 475, in handle_exception
    self.raise_uncaught_exception(exc)
  File "F:\PycharmProfessional\2024-1-1\c\projects\PoultrySync\u200f\.venv\Lib\site-packages\rest_framework\views.py", line 486, in raise_uncaught_exception
    raise exc
  File "F:\PycharmProfessional\2024-1-1\c\projects\PoultrySync\u200f\.venv\Lib\site-packages\rest_framework\views.py", line 512, in dispatch
    response = handler(request, *args, **kwargs)
               ^^^^^^^^^^^^^^^^^^^^^^^^^^^^^^^^^
  File "F:\PycharmProfessional\2024-1-1\c\projects\PoultrySync\u200f\.venv\Lib\site-packages\rest_framework\mixins.py", line 82, in partial_update
    return self.update(request, *args, **kwargs)
           ^^^^^^^^^^^^^^^^^^^^^^^^^^^^^^^^^^^^^
  File "F:\PycharmProfessional\2024-1-1\c\projects\PoultrySync\u200f\.venv\Lib\site-packages\rest_framework\mixins.py", line 65, in update
    instance = self.get_object()
               ^^^^^^^^^^^^^^^^^
  File "F:\PycharmProfessional\2024-1-1\c\projects\PoultrySync\u200f\.venv\Lib\site-packages\rest_framework\generics.py", line 103, in get_object
    self.check_object_permissions(self.request, obj)
  File "F:\PycharmProfessional\2024-1-1\c\projects\PoultrySync\u200f\.venv\Lib\site-packages\rest_framework\views.py", line 351, in check_object_permissions
    if not permission.has_object_permission(request, self, obj):
           ^^^^^^^^^^^^^^^^^^^^^^^^^^^^^^^^^^^^^^^^^^^^^^^^^^^^
  File "F:\PycharmProfessional\2024-1-1\c\projects\PoultrySync\u200f\orders\permissions.py", line 15, in has_object_permission
    return obj.created_at.date() == datetime.date.today()
           ^^^^^^^^^^^^^^^^^^^
AttributeError: 'NoneType' object has no attribute 'date'
INFO:django.utils.autoreload:F:\PycharmProfessional\2024-1-1\c\projects\PoultrySync\u200f\orders\permissions.py changed, reloading.
ERROR:django.request:Internal Server Error: /api/orders/4/
Traceback (most recent call last):
  File "F:\PycharmProfessional\2024-1-1\c\projects\PoultrySync\u200f\.venv\Lib\site-packages\django\core\handlers\exception.py", line 55, in inner
    response = get_response(request)
               ^^^^^^^^^^^^^^^^^^^^^
  File "F:\PycharmProfessional\2024-1-1\c\projects\PoultrySync\u200f\.venv\Lib\site-packages\django\core\handlers\base.py", line 197, in _get_response
    response = wrapped_callback(request, *callback_args, **callback_kwargs)
               ^^^^^^^^^^^^^^^^^^^^^^^^^^^^^^^^^^^^^^^^^^^^^^^^^^^^^^^^^^^^
  File "F:\PycharmProfessional\2024-1-1\c\projects\PoultrySync\u200f\.venv\Lib\site-packages\django\views\decorators\csrf.py", line 56, in wrapper_view
    return view_func(*args, **kwargs)
           ^^^^^^^^^^^^^^^^^^^^^^^^^^
  File "F:\PycharmProfessional\2024-1-1\c\projects\PoultrySync\u200f\.venv\Lib\site-packages\rest_framework\viewsets.py", line 125, in view
    return self.dispatch(request, *args, **kwargs)
           ^^^^^^^^^^^^^^^^^^^^^^^^^^^^^^^^^^^^^^^
  File "F:\PycharmProfessional\2024-1-1\c\projects\PoultrySync\u200f\.venv\Lib\site-packages\rest_framework\views.py", line 515, in dispatch
    response = self.handle_exception(exc)
               ^^^^^^^^^^^^^^^^^^^^^^^^^^
  File "F:\PycharmProfessional\2024-1-1\c\projects\PoultrySync\u200f\.venv\Lib\site-packages\rest_framework\views.py", line 475, in handle_exception
    self.raise_uncaught_exception(exc)
  File "F:\PycharmProfessional\2024-1-1\c\projects\PoultrySync\u200f\.venv\Lib\site-packages\rest_framework\views.py", line 486, in raise_uncaught_exception
    raise exc
  File "F:\PycharmProfessional\2024-1-1\c\projects\PoultrySync\u200f\.venv\Lib\site-packages\rest_framework\views.py", line 512, in dispatch
    response = handler(request, *args, **kwargs)
               ^^^^^^^^^^^^^^^^^^^^^^^^^^^^^^^^^
  File "F:\PycharmProfessional\2024-1-1\c\projects\PoultrySync\u200f\.venv\Lib\site-packages\rest_framework\mixins.py", line 82, in partial_update
    return self.update(request, *args, **kwargs)
           ^^^^^^^^^^^^^^^^^^^^^^^^^^^^^^^^^^^^^
  File "F:\PycharmProfessional\2024-1-1\c\projects\PoultrySync\u200f\.venv\Lib\site-packages\rest_framework\mixins.py", line 65, in update
    instance = self.get_object()
               ^^^^^^^^^^^^^^^^^
  File "F:\PycharmProfessional\2024-1-1\c\projects\PoultrySync\u200f\.venv\Lib\site-packages\rest_framework\generics.py", line 103, in get_object
    self.check_object_permissions(self.request, obj)
  File "F:\PycharmProfessional\2024-1-1\c\projects\PoultrySync\u200f\.venv\Lib\site-packages\rest_framework\views.py", line 351, in check_object_permissions
    if not permission.has_object_permission(request, self, obj):
           ^^^^^^^^^^^^^^^^^^^^^^^^^^^^^^^^^^^^^^^^^^^^^^^^^^^^
  File "F:\PycharmProfessional\2024-1-1\c\projects\PoultrySync\u200f\orders\permissions.py", line 16, in has_object_permission
    return obj.created_at.date() == datetime.date.today()
           ^^^^^^^^^^^^^^^^^^^
AttributeError: 'NoneType' object has no attribute 'date'
INFO:django.utils.autoreload:F:\PycharmProfessional\2024-1-1\c\projects\PoultrySync\u200f\orders\permissions.py changed, reloading.
INFO:django.utils.autoreload:F:\PycharmProfessional\2024-1-1\c\projects\PoultrySync\u200f\orders\permissions.py changed, reloading.
ERROR:django.request:Internal Server Error: /api/orders/4/
Traceback (most recent call last):
  File "F:\PycharmProfessional\2024-1-1\c\projects\PoultrySync\u200f\.venv\Lib\site-packages\django\core\handlers\exception.py", line 55, in inner
    response = get_response(request)
               ^^^^^^^^^^^^^^^^^^^^^
  File "F:\PycharmProfessional\2024-1-1\c\projects\PoultrySync\u200f\.venv\Lib\site-packages\django\core\handlers\base.py", line 197, in _get_response
    response = wrapped_callback(request, *callback_args, **callback_kwargs)
               ^^^^^^^^^^^^^^^^^^^^^^^^^^^^^^^^^^^^^^^^^^^^^^^^^^^^^^^^^^^^
  File "F:\PycharmProfessional\2024-1-1\c\projects\PoultrySync\u200f\.venv\Lib\site-packages\django\views\decorators\csrf.py", line 56, in wrapper_view
    return view_func(*args, **kwargs)
           ^^^^^^^^^^^^^^^^^^^^^^^^^^
  File "F:\PycharmProfessional\2024-1-1\c\projects\PoultrySync\u200f\.venv\Lib\site-packages\rest_framework\viewsets.py", line 125, in view
    return self.dispatch(request, *args, **kwargs)
           ^^^^^^^^^^^^^^^^^^^^^^^^^^^^^^^^^^^^^^^
  File "F:\PycharmProfessional\2024-1-1\c\projects\PoultrySync\u200f\.venv\Lib\site-packages\rest_framework\views.py", line 515, in dispatch
    response = self.handle_exception(exc)
               ^^^^^^^^^^^^^^^^^^^^^^^^^^
  File "F:\PycharmProfessional\2024-1-1\c\projects\PoultrySync\u200f\.venv\Lib\site-packages\rest_framework\views.py", line 475, in handle_exception
    self.raise_uncaught_exception(exc)
  File "F:\PycharmProfessional\2024-1-1\c\projects\PoultrySync\u200f\.venv\Lib\site-packages\rest_framework\views.py", line 486, in raise_uncaught_exception
    raise exc
  File "F:\PycharmProfessional\2024-1-1\c\projects\PoultrySync\u200f\.venv\Lib\site-packages\rest_framework\views.py", line 512, in dispatch
    response = handler(request, *args, **kwargs)
               ^^^^^^^^^^^^^^^^^^^^^^^^^^^^^^^^^
  File "F:\PycharmProfessional\2024-1-1\c\projects\PoultrySync\u200f\.venv\Lib\site-packages\rest_framework\mixins.py", line 82, in partial_update
    return self.update(request, *args, **kwargs)
           ^^^^^^^^^^^^^^^^^^^^^^^^^^^^^^^^^^^^^
  File "F:\PycharmProfessional\2024-1-1\c\projects\PoultrySync\u200f\.venv\Lib\site-packages\rest_framework\mixins.py", line 65, in update
    instance = self.get_object()
               ^^^^^^^^^^^^^^^^^
  File "F:\PycharmProfessional\2024-1-1\c\projects\PoultrySync\u200f\.venv\Lib\site-packages\rest_framework\generics.py", line 103, in get_object
    self.check_object_permissions(self.request, obj)
  File "F:\PycharmProfessional\2024-1-1\c\projects\PoultrySync\u200f\.venv\Lib\site-packages\rest_framework\views.py", line 351, in check_object_permissions
    if not permission.has_object_permission(request, self, obj):
           ^^^^^^^^^^^^^^^^^^^^^^^^^^^^^^^^^^^^^^^^^^^^^^^^^^^^
  File "F:\PycharmProfessional\2024-1-1\c\projects\PoultrySync\u200f\orders\permissions.py", line 16, in has_object_permission
    return obj.created_at.date() == datetime.date.today()
           ^^^^^^^^^^^^^^^^^^^
AttributeError: 'NoneType' object has no attribute 'date'
INFO:django.utils.autoreload:F:\PycharmProfessional\2024-1-1\c\projects\PoultrySync\u200f\orders\models.py changed, reloading.
ERROR:django.request:Internal Server Error: /api/orders/4/
Traceback (most recent call last):
  File "F:\PycharmProfessional\2024-1-1\c\projects\PoultrySync\u200f\.venv\Lib\site-packages\django\core\handlers\exception.py", line 55, in inner
    response = get_response(request)
               ^^^^^^^^^^^^^^^^^^^^^
  File "F:\PycharmProfessional\2024-1-1\c\projects\PoultrySync\u200f\.venv\Lib\site-packages\django\core\handlers\base.py", line 197, in _get_response
    response = wrapped_callback(request, *callback_args, **callback_kwargs)
               ^^^^^^^^^^^^^^^^^^^^^^^^^^^^^^^^^^^^^^^^^^^^^^^^^^^^^^^^^^^^
  File "F:\PycharmProfessional\2024-1-1\c\projects\PoultrySync\u200f\.venv\Lib\site-packages\django\views\decorators\csrf.py", line 56, in wrapper_view
    return view_func(*args, **kwargs)
           ^^^^^^^^^^^^^^^^^^^^^^^^^^
  File "F:\PycharmProfessional\2024-1-1\c\projects\PoultrySync\u200f\.venv\Lib\site-packages\rest_framework\viewsets.py", line 125, in view
    return self.dispatch(request, *args, **kwargs)
           ^^^^^^^^^^^^^^^^^^^^^^^^^^^^^^^^^^^^^^^
  File "F:\PycharmProfessional\2024-1-1\c\projects\PoultrySync\u200f\.venv\Lib\site-packages\rest_framework\views.py", line 515, in dispatch
    response = self.handle_exception(exc)
               ^^^^^^^^^^^^^^^^^^^^^^^^^^
  File "F:\PycharmProfessional\2024-1-1\c\projects\PoultrySync\u200f\.venv\Lib\site-packages\rest_framework\views.py", line 475, in handle_exception
    self.raise_uncaught_exception(exc)
  File "F:\PycharmProfessional\2024-1-1\c\projects\PoultrySync\u200f\.venv\Lib\site-packages\rest_framework\views.py", line 486, in raise_uncaught_exception
    raise exc
  File "F:\PycharmProfessional\2024-1-1\c\projects\PoultrySync\u200f\.venv\Lib\site-packages\rest_framework\views.py", line 512, in dispatch
    response = handler(request, *args, **kwargs)
               ^^^^^^^^^^^^^^^^^^^^^^^^^^^^^^^^^
  File "F:\PycharmProfessional\2024-1-1\c\projects\PoultrySync\u200f\.venv\Lib\site-packages\rest_framework\mixins.py", line 82, in partial_update
    return self.update(request, *args, **kwargs)
           ^^^^^^^^^^^^^^^^^^^^^^^^^^^^^^^^^^^^^
  File "F:\PycharmProfessional\2024-1-1\c\projects\PoultrySync\u200f\.venv\Lib\site-packages\rest_framework\mixins.py", line 65, in update
    instance = self.get_object()
               ^^^^^^^^^^^^^^^^^
  File "F:\PycharmProfessional\2024-1-1\c\projects\PoultrySync\u200f\.venv\Lib\site-packages\rest_framework\generics.py", line 103, in get_object
    self.check_object_permissions(self.request, obj)
  File "F:\PycharmProfessional\2024-1-1\c\projects\PoultrySync\u200f\.venv\Lib\site-packages\rest_framework\views.py", line 351, in check_object_permissions
    if not permission.has_object_permission(request, self, obj):
           ^^^^^^^^^^^^^^^^^^^^^^^^^^^^^^^^^^^^^^^^^^^^^^^^^^^^
  File "F:\PycharmProfessional\2024-1-1\c\projects\PoultrySync\u200f\orders\permissions.py", line 16, in has_object_permission
    return obj.created_at.date() == datetime.date.today()
           ^^^^^^^^^^^^^^^^^^^
AttributeError: 'NoneType' object has no attribute 'date'
ERROR:django.request:Internal Server Error: /api/orders/4/
Traceback (most recent call last):
  File "F:\PycharmProfessional\2024-1-1\c\projects\PoultrySync\u200f\.venv\Lib\site-packages\django\core\handlers\exception.py", line 55, in inner
    response = get_response(request)
               ^^^^^^^^^^^^^^^^^^^^^
  File "F:\PycharmProfessional\2024-1-1\c\projects\PoultrySync\u200f\.venv\Lib\site-packages\django\core\handlers\base.py", line 197, in _get_response
    response = wrapped_callback(request, *callback_args, **callback_kwargs)
               ^^^^^^^^^^^^^^^^^^^^^^^^^^^^^^^^^^^^^^^^^^^^^^^^^^^^^^^^^^^^
  File "F:\PycharmProfessional\2024-1-1\c\projects\PoultrySync\u200f\.venv\Lib\site-packages\django\views\decorators\csrf.py", line 56, in wrapper_view
    return view_func(*args, **kwargs)
           ^^^^^^^^^^^^^^^^^^^^^^^^^^
  File "F:\PycharmProfessional\2024-1-1\c\projects\PoultrySync\u200f\.venv\Lib\site-packages\rest_framework\viewsets.py", line 125, in view
    return self.dispatch(request, *args, **kwargs)
           ^^^^^^^^^^^^^^^^^^^^^^^^^^^^^^^^^^^^^^^
  File "F:\PycharmProfessional\2024-1-1\c\projects\PoultrySync\u200f\.venv\Lib\site-packages\rest_framework\views.py", line 515, in dispatch
    response = self.handle_exception(exc)
               ^^^^^^^^^^^^^^^^^^^^^^^^^^
  File "F:\PycharmProfessional\2024-1-1\c\projects\PoultrySync\u200f\.venv\Lib\site-packages\rest_framework\views.py", line 475, in handle_exception
    self.raise_uncaught_exception(exc)
  File "F:\PycharmProfessional\2024-1-1\c\projects\PoultrySync\u200f\.venv\Lib\site-packages\rest_framework\views.py", line 486, in raise_uncaught_exception
    raise exc
  File "F:\PycharmProfessional\2024-1-1\c\projects\PoultrySync\u200f\.venv\Lib\site-packages\rest_framework\views.py", line 512, in dispatch
    response = handler(request, *args, **kwargs)
               ^^^^^^^^^^^^^^^^^^^^^^^^^^^^^^^^^
  File "F:\PycharmProfessional\2024-1-1\c\projects\PoultrySync\u200f\.venv\Lib\site-packages\rest_framework\mixins.py", line 82, in partial_update
    return self.update(request, *args, **kwargs)
           ^^^^^^^^^^^^^^^^^^^^^^^^^^^^^^^^^^^^^
  File "F:\PycharmProfessional\2024-1-1\c\projects\PoultrySync\u200f\.venv\Lib\site-packages\rest_framework\mixins.py", line 65, in update
    instance = self.get_object()
               ^^^^^^^^^^^^^^^^^
  File "F:\PycharmProfessional\2024-1-1\c\projects\PoultrySync\u200f\.venv\Lib\site-packages\rest_framework\generics.py", line 103, in get_object
    self.check_object_permissions(self.request, obj)
  File "F:\PycharmProfessional\2024-1-1\c\projects\PoultrySync\u200f\.venv\Lib\site-packages\rest_framework\views.py", line 351, in check_object_permissions
    if not permission.has_object_permission(request, self, obj):
           ^^^^^^^^^^^^^^^^^^^^^^^^^^^^^^^^^^^^^^^^^^^^^^^^^^^^
  File "F:\PycharmProfessional\2024-1-1\c\projects\PoultrySync\u200f\orders\permissions.py", line 16, in has_object_permission
    return obj.created_at.date() == datetime.date.today()
           ^^^^^^^^^^^^^^^^^^^
AttributeError: 'NoneType' object has no attribute 'date'
WARNING:django.request:Not Found: /api/orders/4/
WARNING:django.request:Forbidden: /api/orders/5/
INFO:django.utils.autoreload:F:\PycharmProfessional\2024-1-1\c\projects\PoultrySync\u200f\orders\permissions.py changed, reloading.
WARNING:django.request:Forbidden: /api/orders/5/
INFO:django.utils.autoreload:F:\PycharmProfessional\2024-1-1\c\projects\PoultrySync\u200f\orders\permissions.py changed, reloading.
ERROR:django.request:Internal Server Error: /api/orders/5/
Traceback (most recent call last):
  File "F:\PycharmProfessional\2024-1-1\c\projects\PoultrySync\u200f\.venv\Lib\site-packages\django\core\handlers\exception.py", line 55, in inner
    response = get_response(request)
               ^^^^^^^^^^^^^^^^^^^^^
  File "F:\PycharmProfessional\2024-1-1\c\projects\PoultrySync\u200f\.venv\Lib\site-packages\django\core\handlers\base.py", line 197, in _get_response
    response = wrapped_callback(request, *callback_args, **callback_kwargs)
               ^^^^^^^^^^^^^^^^^^^^^^^^^^^^^^^^^^^^^^^^^^^^^^^^^^^^^^^^^^^^
  File "F:\PycharmProfessional\2024-1-1\c\projects\PoultrySync\u200f\.venv\Lib\site-packages\django\views\decorators\csrf.py", line 56, in wrapper_view
    return view_func(*args, **kwargs)
           ^^^^^^^^^^^^^^^^^^^^^^^^^^
  File "F:\PycharmProfessional\2024-1-1\c\projects\PoultrySync\u200f\.venv\Lib\site-packages\rest_framework\viewsets.py", line 125, in view
    return self.dispatch(request, *args, **kwargs)
           ^^^^^^^^^^^^^^^^^^^^^^^^^^^^^^^^^^^^^^^
  File "F:\PycharmProfessional\2024-1-1\c\projects\PoultrySync\u200f\.venv\Lib\site-packages\rest_framework\views.py", line 515, in dispatch
    response = self.handle_exception(exc)
               ^^^^^^^^^^^^^^^^^^^^^^^^^^
  File "F:\PycharmProfessional\2024-1-1\c\projects\PoultrySync\u200f\.venv\Lib\site-packages\rest_framework\views.py", line 475, in handle_exception
    self.raise_uncaught_exception(exc)
  File "F:\PycharmProfessional\2024-1-1\c\projects\PoultrySync\u200f\.venv\Lib\site-packages\rest_framework\views.py", line 486, in raise_uncaught_exception
    raise exc
  File "F:\PycharmProfessional\2024-1-1\c\projects\PoultrySync\u200f\.venv\Lib\site-packages\rest_framework\views.py", line 512, in dispatch
    response = handler(request, *args, **kwargs)
               ^^^^^^^^^^^^^^^^^^^^^^^^^^^^^^^^^
  File "F:\PycharmProfessional\2024-1-1\c\projects\PoultrySync\u200f\.venv\Lib\site-packages\rest_framework\mixins.py", line 82, in partial_update
    return self.update(request, *args, **kwargs)
           ^^^^^^^^^^^^^^^^^^^^^^^^^^^^^^^^^^^^^
  File "F:\PycharmProfessional\2024-1-1\c\projects\PoultrySync\u200f\.venv\Lib\site-packages\rest_framework\mixins.py", line 65, in update
    instance = self.get_object()
               ^^^^^^^^^^^^^^^^^
  File "F:\PycharmProfessional\2024-1-1\c\projects\PoultrySync\u200f\.venv\Lib\site-packages\rest_framework\generics.py", line 103, in get_object
    self.check_object_permissions(self.request, obj)
  File "F:\PycharmProfessional\2024-1-1\c\projects\PoultrySync\u200f\.venv\Lib\site-packages\rest_framework\views.py", line 351, in check_object_permissions
    if not permission.has_object_permission(request, self, obj):
           ^^^^^^^^^^^^^^^^^^^^^^^^^^^^^^^^^^^^^^^^^^^^^^^^^^^^
  File "F:\PycharmProfessional\2024-1-1\c\projects\PoultrySync\u200f\orders\permissions.py", line 16, in has_object_permission
    return obj.created_at.date() == datetime.utcnow().date.today()
                                    ^^^^^^^^^^^^^^^
AttributeError: module 'datetime' has no attribute 'utcnow'
INFO:django.utils.autoreload:F:\PycharmProfessional\2024-1-1\c\projects\PoultrySync\u200f\orders\permissions.py changed, reloading.
ERROR:django.request:Internal Server Error: /api/orders/5/
Traceback (most recent call last):
  File "F:\PycharmProfessional\2024-1-1\c\projects\PoultrySync\u200f\.venv\Lib\site-packages\django\core\handlers\exception.py", line 55, in inner
    response = get_response(request)
               ^^^^^^^^^^^^^^^^^^^^^
  File "F:\PycharmProfessional\2024-1-1\c\projects\PoultrySync\u200f\.venv\Lib\site-packages\django\core\handlers\base.py", line 197, in _get_response
    response = wrapped_callback(request, *callback_args, **callback_kwargs)
               ^^^^^^^^^^^^^^^^^^^^^^^^^^^^^^^^^^^^^^^^^^^^^^^^^^^^^^^^^^^^
  File "F:\PycharmProfessional\2024-1-1\c\projects\PoultrySync\u200f\.venv\Lib\site-packages\django\views\decorators\csrf.py", line 56, in wrapper_view
    return view_func(*args, **kwargs)
           ^^^^^^^^^^^^^^^^^^^^^^^^^^
  File "F:\PycharmProfessional\2024-1-1\c\projects\PoultrySync\u200f\.venv\Lib\site-packages\rest_framework\viewsets.py", line 125, in view
    return self.dispatch(request, *args, **kwargs)
           ^^^^^^^^^^^^^^^^^^^^^^^^^^^^^^^^^^^^^^^
  File "F:\PycharmProfessional\2024-1-1\c\projects\PoultrySync\u200f\.venv\Lib\site-packages\rest_framework\views.py", line 515, in dispatch
    response = self.handle_exception(exc)
               ^^^^^^^^^^^^^^^^^^^^^^^^^^
  File "F:\PycharmProfessional\2024-1-1\c\projects\PoultrySync\u200f\.venv\Lib\site-packages\rest_framework\views.py", line 475, in handle_exception
    self.raise_uncaught_exception(exc)
  File "F:\PycharmProfessional\2024-1-1\c\projects\PoultrySync\u200f\.venv\Lib\site-packages\rest_framework\views.py", line 486, in raise_uncaught_exception
    raise exc
  File "F:\PycharmProfessional\2024-1-1\c\projects\PoultrySync\u200f\.venv\Lib\site-packages\rest_framework\views.py", line 512, in dispatch
    response = handler(request, *args, **kwargs)
               ^^^^^^^^^^^^^^^^^^^^^^^^^^^^^^^^^
  File "F:\PycharmProfessional\2024-1-1\c\projects\PoultrySync\u200f\.venv\Lib\site-packages\rest_framework\mixins.py", line 82, in partial_update
    return self.update(request, *args, **kwargs)
           ^^^^^^^^^^^^^^^^^^^^^^^^^^^^^^^^^^^^^
  File "F:\PycharmProfessional\2024-1-1\c\projects\PoultrySync\u200f\.venv\Lib\site-packages\rest_framework\mixins.py", line 65, in update
    instance = self.get_object()
               ^^^^^^^^^^^^^^^^^
  File "F:\PycharmProfessional\2024-1-1\c\projects\PoultrySync\u200f\.venv\Lib\site-packages\rest_framework\generics.py", line 103, in get_object
    self.check_object_permissions(self.request, obj)
  File "F:\PycharmProfessional\2024-1-1\c\projects\PoultrySync\u200f\.venv\Lib\site-packages\rest_framework\views.py", line 351, in check_object_permissions
    if not permission.has_object_permission(request, self, obj):
           ^^^^^^^^^^^^^^^^^^^^^^^^^^^^^^^^^^^^^^^^^^^^^^^^^^^^
  File "F:\PycharmProfessional\2024-1-1\c\projects\PoultrySync\u200f\orders\permissions.py", line 16, in has_object_permission
    return obj.created_at.date() == datetime.datetime.utcnow().date.today()
                                    ^^^^^^^^^^^^^^^^^^^^^^^^^^^^^^^^^^^^^
AttributeError: 'builtin_function_or_method' object has no attribute 'today'
INFO:django.utils.autoreload:F:\PycharmProfessional\2024-1-1\c\projects\PoultrySync\u200f\orders\permissions.py changed, reloading.
WARNING:django.request:Forbidden: /api/orders/5/
INFO:django.utils.autoreload:F:\PycharmProfessional\2024-1-1\c\projects\PoultrySync\u200f\orders\permissions.py changed, reloading.
WARNING:django.request:Bad Request: /api/orders/5/
INFO:django.utils.autoreload:F:\PycharmProfessional\2024-1-1\c\projects\PoultrySync\u200f\orders\permissions.py changed, reloading.
WARNING:django.request:Bad Request: /api/orders/5/
ERROR:django.request:Internal Server Error: /api/orders/5/
Traceback (most recent call last):
  File "F:\PycharmProfessional\2024-1-1\c\projects\PoultrySync\u200f\.venv\Lib\site-packages\django\core\handlers\exception.py", line 55, in inner
    response = get_response(request)
               ^^^^^^^^^^^^^^^^^^^^^
  File "F:\PycharmProfessional\2024-1-1\c\projects\PoultrySync\u200f\.venv\Lib\site-packages\django\core\handlers\base.py", line 197, in _get_response
    response = wrapped_callback(request, *callback_args, **callback_kwargs)
               ^^^^^^^^^^^^^^^^^^^^^^^^^^^^^^^^^^^^^^^^^^^^^^^^^^^^^^^^^^^^
  File "F:\PycharmProfessional\2024-1-1\c\projects\PoultrySync\u200f\.venv\Lib\site-packages\django\views\decorators\csrf.py", line 56, in wrapper_view
    return view_func(*args, **kwargs)
           ^^^^^^^^^^^^^^^^^^^^^^^^^^
  File "F:\PycharmProfessional\2024-1-1\c\projects\PoultrySync\u200f\.venv\Lib\site-packages\rest_framework\viewsets.py", line 125, in view
    return self.dispatch(request, *args, **kwargs)
           ^^^^^^^^^^^^^^^^^^^^^^^^^^^^^^^^^^^^^^^
  File "F:\PycharmProfessional\2024-1-1\c\projects\PoultrySync\u200f\.venv\Lib\site-packages\rest_framework\views.py", line 515, in dispatch
    response = self.handle_exception(exc)
               ^^^^^^^^^^^^^^^^^^^^^^^^^^
  File "F:\PycharmProfessional\2024-1-1\c\projects\PoultrySync\u200f\.venv\Lib\site-packages\rest_framework\views.py", line 475, in handle_exception
    self.raise_uncaught_exception(exc)
  File "F:\PycharmProfessional\2024-1-1\c\projects\PoultrySync\u200f\.venv\Lib\site-packages\rest_framework\views.py", line 486, in raise_uncaught_exception
    raise exc
  File "F:\PycharmProfessional\2024-1-1\c\projects\PoultrySync\u200f\.venv\Lib\site-packages\rest_framework\views.py", line 512, in dispatch
    response = handler(request, *args, **kwargs)
               ^^^^^^^^^^^^^^^^^^^^^^^^^^^^^^^^^
  File "F:\PycharmProfessional\2024-1-1\c\projects\PoultrySync\u200f\.venv\Lib\site-packages\rest_framework\mixins.py", line 82, in partial_update
    return self.update(request, *args, **kwargs)
           ^^^^^^^^^^^^^^^^^^^^^^^^^^^^^^^^^^^^^
  File "F:\PycharmProfessional\2024-1-1\c\projects\PoultrySync\u200f\.venv\Lib\site-packages\rest_framework\mixins.py", line 67, in update
    serializer.is_valid(raise_exception=True)
  File "F:\PycharmProfessional\2024-1-1\c\projects\PoultrySync\u200f\.venv\Lib\site-packages\rest_framework\serializers.py", line 225, in is_valid
    self._validated_data = self.run_validation(self.initial_data)
                           ^^^^^^^^^^^^^^^^^^^^^^^^^^^^^^^^^^^^^^
  File "F:\PycharmProfessional\2024-1-1\c\projects\PoultrySync\u200f\.venv\Lib\site-packages\rest_framework\serializers.py", line 447, in run_validation
    value = self.validate(value)
            ^^^^^^^^^^^^^^^^^^^^
  File "F:\PycharmProfessional\2024-1-1\c\projects\PoultrySync\u200f\orders\serializers.py", line 23, in validate
    product = data['product']
              ~~~~^^^^^^^^^^^
KeyError: 'product'
INFO:django.utils.autoreload:F:\PycharmProfessional\2024-1-1\c\projects\PoultrySync\u200f\orders\serializers.py changed, reloading.
WARNING:drf_yasg.inspectors.base:view's ProductViewSet raised exception during schema generation; use `getattr(self, 'swagger_fake_view', False)` to detect and short-circuit this
Traceback (most recent call last):
  File "F:\PycharmProfessional\2024-1-1\c\projects\PoultrySync\u200f\.venv\Lib\site-packages\drf_yasg\inspectors\base.py", line 42, in call_view_method
    return view_method()
           ^^^^^^^^^^^^^
  File "F:\PycharmProfessional\2024-1-1\c\projects\PoultrySync\u200f\orders\views.py", line 24, in get_queryset
    return Product.objects.filter(company=self.request.user.company, is_active=True)
                                          ^^^^^^^^^^^^^^^^^^^^^^^^^
AttributeError: 'AnonymousUser' object has no attribute 'company'
WARNING:drf_yasg.inspectors.base:view's OrderViewSet raised exception during schema generation; use `getattr(self, 'swagger_fake_view', False)` to detect and short-circuit this
Traceback (most recent call last):
  File "F:\PycharmProfessional\2024-1-1\c\projects\PoultrySync\u200f\.venv\Lib\site-packages\drf_yasg\inspectors\base.py", line 42, in call_view_method
    return view_method()
           ^^^^^^^^^^^^^
  File "F:\PycharmProfessional\2024-1-1\c\projects\PoultrySync\u200f\orders\views.py", line 35, in get_queryset
    return Order.objects.filter(company=self.request.user.company)
                                        ^^^^^^^^^^^^^^^^^^^^^^^^^
AttributeError: 'AnonymousUser' object has no attribute 'company'
WARNING:drf_yasg.inspectors.base:view's ProductViewSet raised exception during schema generation; use `getattr(self, 'swagger_fake_view', False)` to detect and short-circuit this
Traceback (most recent call last):
  File "F:\PycharmProfessional\2024-1-1\c\projects\PoultrySync\u200f\.venv\Lib\site-packages\drf_yasg\inspectors\base.py", line 42, in call_view_method
    return view_method()
           ^^^^^^^^^^^^^
  File "F:\PycharmProfessional\2024-1-1\c\projects\PoultrySync\u200f\orders\views.py", line 24, in get_queryset
    return Product.objects.filter(company=self.request.user.company, is_active=True)
                                          ^^^^^^^^^^^^^^^^^^^^^^^^^
AttributeError: 'AnonymousUser' object has no attribute 'company'
WARNING:drf_yasg.inspectors.base:view's OrderViewSet raised exception during schema generation; use `getattr(self, 'swagger_fake_view', False)` to detect and short-circuit this
Traceback (most recent call last):
  File "F:\PycharmProfessional\2024-1-1\c\projects\PoultrySync\u200f\.venv\Lib\site-packages\drf_yasg\inspectors\base.py", line 42, in call_view_method
    return view_method()
           ^^^^^^^^^^^^^
  File "F:\PycharmProfessional\2024-1-1\c\projects\PoultrySync\u200f\orders\views.py", line 35, in get_queryset
    return Order.objects.filter(company=self.request.user.company)
                                        ^^^^^^^^^^^^^^^^^^^^^^^^^
AttributeError: 'AnonymousUser' object has no attribute 'company'
WARNING:drf_yasg.inspectors.base:view's ProductViewSet raised exception during schema generation; use `getattr(self, 'swagger_fake_view', False)` to detect and short-circuit this
Traceback (most recent call last):
  File "F:\PycharmProfessional\2024-1-1\c\projects\PoultrySync\u200f\.venv\Lib\site-packages\drf_yasg\inspectors\base.py", line 42, in call_view_method
    return view_method()
           ^^^^^^^^^^^^^
  File "F:\PycharmProfessional\2024-1-1\c\projects\PoultrySync\u200f\orders\views.py", line 24, in get_queryset
    return Product.objects.filter(company=self.request.user.company, is_active=True)
                                          ^^^^^^^^^^^^^^^^^^^^^^^^^
AttributeError: 'AnonymousUser' object has no attribute 'company'
WARNING:drf_yasg.inspectors.base:view's OrderViewSet raised exception during schema generation; use `getattr(self, 'swagger_fake_view', False)` to detect and short-circuit this
Traceback (most recent call last):
  File "F:\PycharmProfessional\2024-1-1\c\projects\PoultrySync\u200f\.venv\Lib\site-packages\drf_yasg\inspectors\base.py", line 42, in call_view_method
    return view_method()
           ^^^^^^^^^^^^^
  File "F:\PycharmProfessional\2024-1-1\c\projects\PoultrySync\u200f\orders\views.py", line 35, in get_queryset
    return Order.objects.filter(company=self.request.user.company)
                                        ^^^^^^^^^^^^^^^^^^^^^^^^^
AttributeError: 'AnonymousUser' object has no attribute 'company'
WARNING:drf_yasg.inspectors.base:view's ProductViewSet raised exception during schema generation; use `getattr(self, 'swagger_fake_view', False)` to detect and short-circuit this
Traceback (most recent call last):
  File "F:\PycharmProfessional\2024-1-1\c\projects\PoultrySync\u200f\.venv\Lib\site-packages\drf_yasg\inspectors\base.py", line 42, in call_view_method
    return view_method()
           ^^^^^^^^^^^^^
  File "F:\PycharmProfessional\2024-1-1\c\projects\PoultrySync\u200f\orders\views.py", line 24, in get_queryset
    return Product.objects.filter(company=self.request.user.company, is_active=True)
                                          ^^^^^^^^^^^^^^^^^^^^^^^^^
AttributeError: 'AnonymousUser' object has no attribute 'company'
WARNING:drf_yasg.inspectors.base:view's OrderViewSet raised exception during schema generation; use `getattr(self, 'swagger_fake_view', False)` to detect and short-circuit this
Traceback (most recent call last):
  File "F:\PycharmProfessional\2024-1-1\c\projects\PoultrySync\u200f\.venv\Lib\site-packages\drf_yasg\inspectors\base.py", line 42, in call_view_method
    return view_method()
           ^^^^^^^^^^^^^
  File "F:\PycharmProfessional\2024-1-1\c\projects\PoultrySync\u200f\orders\views.py", line 35, in get_queryset
    return Order.objects.filter(company=self.request.user.company)
                                        ^^^^^^^^^^^^^^^^^^^^^^^^^
AttributeError: 'AnonymousUser' object has no attribute 'company'
INFO:django.utils.autoreload:F:\PycharmProfessional\2024-1-1\c\projects\PoultrySync\u200f\orders\serializers.py changed, reloading.
INFO:django.utils.autoreload:F:\PycharmProfessional\2024-1-1\c\projects\PoultrySync\u200f\orders\permissions.py changed, reloading.
